================================================================================
load pg_denormalized
================================================================================
COPY 10000
COPY 10000
COPY 10000
COPY 10000
COPY 10000
COPY 10000
COPY 10000
COPY 10000
COPY 10000
COPY 10000
5.39user 1.56system 0:04.04elapsed 172%CPU (0avgtext+0avgdata 17716maxresident)k
108360inputs+2800outputs (0major+52813minor)pagefaults 0swaps
================================================================================
load pg_normalized
================================================================================
2024-04-23 13:55:49.231426 data/geoTwitter21-01-03.zip
2024-04-23 13:55:49.258945 data/geoTwitter21-01-03.zip - i= 0 id= 1345520246879346689
2024-04-23 13:55:54.557665 data/geoTwitter21-01-03.zip - i= 1000 id= 1345520358007296002
2024-04-23 13:56:00.183168 data/geoTwitter21-01-03.zip - i= 2000 id= 1345520465599733761
2024-04-23 13:56:05.801046 data/geoTwitter21-01-03.zip - i= 3000 id= 1345520578309054465
2024-04-23 13:56:11.575647 data/geoTwitter21-01-03.zip - i= 4000 id= 1345520688711434240
2024-04-23 13:56:17.487036 data/geoTwitter21-01-03.zip - i= 5000 id= 1345520799013343233
2024-04-23 13:56:23.386815 data/geoTwitter21-01-03.zip - i= 6000 id= 1345520903002730498
2024-04-23 13:56:28.954664 data/geoTwitter21-01-03.zip - i= 7000 id= 1345521009101836290
2024-04-23 13:56:34.489743 data/geoTwitter21-01-03.zip - i= 8000 id= 1345521104564215812
2024-04-23 13:56:40.514466 data/geoTwitter21-01-03.zip - i= 9000 id= 1345521207790235648
2024-04-23 13:55:49.246619 data/geoTwitter21-01-07.zip
2024-04-23 13:55:49.276784 data/geoTwitter21-01-07.zip - i= 0 id= 1346969798157197316
2024-04-23 13:55:54.592748 data/geoTwitter21-01-07.zip - i= 1000 id= 1346969884819787776
2024-04-23 13:56:00.340691 data/geoTwitter21-01-07.zip - i= 2000 id= 1346969972032024576
2024-04-23 13:56:05.843081 data/geoTwitter21-01-07.zip - i= 3000 id= 1346970060900986887
2024-04-23 13:56:11.477705 data/geoTwitter21-01-07.zip - i= 4000 id= 1346970148712849415
2024-04-23 13:56:17.520899 data/geoTwitter21-01-07.zip - i= 5000 id= 1346970235673300992
2024-04-23 13:56:23.580063 data/geoTwitter21-01-07.zip - i= 6000 id= 1346970323246219265
2024-04-23 13:56:29.286662 data/geoTwitter21-01-07.zip - i= 7000 id= 1346970411884453892
2024-04-23 13:56:34.903832 data/geoTwitter21-01-07.zip - i= 8000 id= 1346970500598165508
2024-04-23 13:56:40.974169 data/geoTwitter21-01-07.zip - i= 9000 id= 1346970588720590851
2024-04-23 13:55:49.243296 data/geoTwitter21-01-01.zip
2024-04-23 13:55:49.271201 data/geoTwitter21-01-01.zip - i= 0 id= 1344795471093633031
2024-04-23 13:55:54.380375 data/geoTwitter21-01-01.zip - i= 1000 id= 1344795553989865473
2024-04-23 13:56:00.236920 data/geoTwitter21-01-01.zip - i= 2000 id= 1344795640279265286
2024-04-23 13:56:05.656772 data/geoTwitter21-01-01.zip - i= 3000 id= 1344795728426754049
2024-04-23 13:56:11.222408 data/geoTwitter21-01-01.zip - i= 4000 id= 1344795817517981699
2024-04-23 13:56:17.395044 data/geoTwitter21-01-01.zip - i= 5000 id= 1344795904700796930
2024-04-23 13:56:23.415414 data/geoTwitter21-01-01.zip - i= 6000 id= 1344795992403681281
2024-04-23 13:56:29.208963 data/geoTwitter21-01-01.zip - i= 7000 id= 1344796079125094401
2024-04-23 13:56:34.949909 data/geoTwitter21-01-01.zip - i= 8000 id= 1344796167029346307
2024-04-23 13:56:40.919169 data/geoTwitter21-01-01.zip - i= 9000 id= 1344796254472187911
2024-04-23 13:55:49.232864 data/geoTwitter21-01-10.zip
2024-04-23 13:55:49.264899 data/geoTwitter21-01-10.zip - i= 0 id= 1348056961783312384
2024-04-23 13:55:54.458134 data/geoTwitter21-01-10.zip - i= 1000 id= 1348057063004524545
2024-04-23 13:56:00.131809 data/geoTwitter21-01-10.zip - i= 2000 id= 1348057174644293636
2024-04-23 13:56:05.725911 data/geoTwitter21-01-10.zip - i= 3000 id= 1348057285017350145
2024-04-23 13:56:11.188342 data/geoTwitter21-01-10.zip - i= 4000 id= 1348057392710299648
2024-04-23 13:56:17.041482 data/geoTwitter21-01-10.zip - i= 5000 id= 1348057506946441219
2024-04-23 13:56:23.352125 data/geoTwitter21-01-10.zip - i= 6000 id= 1348057618066116614
2024-04-23 13:56:29.075248 data/geoTwitter21-01-10.zip - i= 7000 id= 1348057727348699137
2024-04-23 13:56:34.871150 data/geoTwitter21-01-10.zip - i= 8000 id= 1348057835763068936
2024-04-23 13:56:41.106249 data/geoTwitter21-01-10.zip - i= 9000 id= 1348057943732858880
2024-04-23 13:55:49.231180 data/geoTwitter21-01-05.zip
2024-04-23 13:55:49.263256 data/geoTwitter21-01-05.zip - i= 0 id= 1346245022325346304
2024-04-23 13:55:54.577407 data/geoTwitter21-01-05.zip - i= 1000 id= 1346245130425159681
2024-04-23 13:56:00.101899 data/geoTwitter21-01-05.zip - i= 2000 id= 1346245244313067521
2024-04-23 13:56:05.487389 data/geoTwitter21-01-05.zip - i= 3000 id= 1346245359744524289
2024-04-23 13:56:10.987284 data/geoTwitter21-01-05.zip - i= 4000 id= 1346245471497375744
2024-04-23 13:56:16.842419 data/geoTwitter21-01-05.zip - i= 5000 id= 1346245580096499715
2024-04-23 13:56:23.122660 data/geoTwitter21-01-05.zip - i= 6000 id= 1346245693745360900
2024-04-23 13:56:28.901613 data/geoTwitter21-01-05.zip - i= 7000 id= 1346245805280260097
2024-04-23 13:56:34.781839 data/geoTwitter21-01-05.zip - i= 8000 id= 1346245913468170241
2024-04-23 13:56:40.926101 data/geoTwitter21-01-05.zip - i= 9000 id= 1346246025791504386
2024-04-23 13:55:49.231882 data/geoTwitter21-01-04.zip
2024-04-23 13:55:49.264707 data/geoTwitter21-01-04.zip - i= 0 id= 1345882634702864384
2024-04-23 13:55:54.618099 data/geoTwitter21-01-04.zip - i= 1000 id= 1345882733856260096
2024-04-23 13:56:00.275537 data/geoTwitter21-01-04.zip - i= 2000 id= 1345882835887005697
2024-04-23 13:56:05.929861 data/geoTwitter21-01-04.zip - i= 3000 id= 1345882930544050185
2024-04-23 13:56:11.405292 data/geoTwitter21-01-04.zip - i= 4000 id= 1345883033593896961
2024-04-23 13:56:17.207864 data/geoTwitter21-01-04.zip - i= 5000 id= 1345883134777307136
2024-04-23 13:56:23.506177 data/geoTwitter21-01-04.zip - i= 6000 id= 1345883235813789696
2024-04-23 13:56:29.276195 data/geoTwitter21-01-04.zip - i= 7000 id= 1345883341543804928
2024-04-23 13:56:35.126614 data/geoTwitter21-01-04.zip - i= 8000 id= 1345883444585385990
2024-04-23 13:56:41.208017 data/geoTwitter21-01-04.zip - i= 9000 id= 1345883542828556288
2024-04-23 13:55:49.275206 data/geoTwitter21-01-06.zip
2024-04-23 13:55:49.307207 data/geoTwitter21-01-06.zip - i= 0 id= 1346607410463571971
2024-04-23 13:55:54.647679 data/geoTwitter21-01-06.zip - i= 1000 id= 1346607509872599040
2024-04-23 13:56:00.350968 data/geoTwitter21-01-06.zip - i= 2000 id= 1346607618035384320
2024-04-23 13:56:05.922726 data/geoTwitter21-01-06.zip - i= 3000 id= 1346607723874549763
2024-04-23 13:56:11.739799 data/geoTwitter21-01-06.zip - i= 4000 id= 1346607828253908994
2024-04-23 13:56:17.902797 data/geoTwitter21-01-06.zip - i= 5000 id= 1346607937658081281
2024-04-23 13:56:24.238870 data/geoTwitter21-01-06.zip - i= 6000 id= 1346608044478750720
2024-04-23 13:56:29.982763 data/geoTwitter21-01-06.zip - i= 7000 id= 1346608156202381312
2024-04-23 13:56:35.689936 data/geoTwitter21-01-06.zip - i= 8000 id= 1346608267175342080
2024-04-23 13:56:41.798693 data/geoTwitter21-01-06.zip - i= 9000 id= 1346608375434510337
2024-04-23 13:55:49.229866 data/geoTwitter21-01-02.zip
2024-04-23 13:55:49.254761 data/geoTwitter21-01-02.zip - i= 0 id= 1345157858732732416
2024-04-23 13:55:54.645675 data/geoTwitter21-01-02.zip - i= 1000 id= 1345157965662322699
2024-04-23 13:56:00.380465 data/geoTwitter21-01-02.zip - i= 2000 id= 1345158082922483720
2024-04-23 13:56:05.872423 data/geoTwitter21-01-02.zip - i= 3000 id= 1345158200153280518
2024-04-23 13:56:11.579016 data/geoTwitter21-01-02.zip - i= 4000 id= 1345158320651444225
2024-04-23 13:56:17.575364 data/geoTwitter21-01-02.zip - i= 5000 id= 1345158438754672641
2024-04-23 13:56:23.837032 data/geoTwitter21-01-02.zip - i= 6000 id= 1345158549882556416
2024-04-23 13:56:29.769332 data/geoTwitter21-01-02.zip - i= 7000 id= 1345158670234112007
2024-04-23 13:56:35.679146 data/geoTwitter21-01-02.zip - i= 8000 id= 1345158786491719680
2024-04-23 13:56:41.995861 data/geoTwitter21-01-02.zip - i= 9000 id= 1345158904876032018
2024-04-23 13:55:49.240589 data/geoTwitter21-01-08.zip
2024-04-23 13:55:49.264957 data/geoTwitter21-01-08.zip - i= 0 id= 1347332185930543104
2024-04-23 13:55:54.830212 data/geoTwitter21-01-08.zip - i= 1000 id= 1347332282340798464
2024-04-23 13:56:00.686120 data/geoTwitter21-01-08.zip - i= 2000 id= 1347332389136191489
2024-04-23 13:56:06.401266 data/geoTwitter21-01-08.zip - i= 3000 id= 1347332491074437120
2024-04-23 13:56:12.347092 data/geoTwitter21-01-08.zip - i= 4000 id= 1347332600864657408
2024-04-23 13:56:18.244277 data/geoTwitter21-01-08.zip - i= 5000 id= 1347332706267496450
2024-04-23 13:56:24.385250 data/geoTwitter21-01-08.zip - i= 6000 id= 1347332810445623298
2024-04-23 13:56:30.087684 data/geoTwitter21-01-08.zip - i= 7000 id= 1347332913856196609
2024-04-23 13:56:35.821666 data/geoTwitter21-01-08.zip - i= 8000 id= 1347333021385551872
2024-04-23 13:56:42.059343 data/geoTwitter21-01-08.zip - i= 9000 id= 1347333130055806976
2024-04-23 13:55:49.230516 data/geoTwitter21-01-09.zip
2024-04-23 13:55:49.258863 data/geoTwitter21-01-09.zip - i= 0 id= 1347694574018453504
2024-04-23 13:55:54.640856 data/geoTwitter21-01-09.zip - i= 1000 id= 1347694663432605696
2024-04-23 13:56:00.380249 data/geoTwitter21-01-09.zip - i= 2000 id= 1347694753442312193
2024-04-23 13:56:06.011655 data/geoTwitter21-01-09.zip - i= 3000 id= 1347694846962769926
2024-04-23 13:56:11.821063 data/geoTwitter21-01-09.zip - i= 4000 id= 1347694940822896640
2024-04-23 13:56:17.953886 data/geoTwitter21-01-09.zip - i= 5000 id= 1347695034255237120
2024-04-23 13:56:24.144266 data/geoTwitter21-01-09.zip - i= 6000 id= 1347695129918722049
2024-04-23 13:56:29.880573 data/geoTwitter21-01-09.zip - i= 7000 id= 1347695222709387268
2024-04-23 13:56:35.699681 data/geoTwitter21-01-09.zip - i= 8000 id= 1347695321917349889
2024-04-23 13:56:42.015658 data/geoTwitter21-01-09.zip - i= 9000 id= 1347695415504891904
282.42user 28.65system 1:00.01elapsed 518%CPU (0avgtext+0avgdata 46472maxresident)k
27904inputs+4288outputs (52major+216523minor)pagefaults 0swaps
================================================================================
load pg_normalized_batch
================================================================================
2024-04-23 13:56:49.216483 data/geoTwitter21-01-01.zip
2024-04-23 13:56:50.286509 insert_tweets i= 0
Traceback (most recent call last):
  File "/home/sfullerton24/twitter_postgres_parallel/load_tweets_batch.py", line 432, in <module>
    insert_tweets(connection,tweets,args.batch_size)
  File "/home/sfullerton24/twitter_postgres_parallel/load_tweets_batch.py", line 149, in insert_tweets
    _insert_tweets(connection, tweet_batch)
  File "/home/sfullerton24/twitter_postgres_parallel/load_tweets_batch.py", line 368, in _insert_tweets
    with connection.begin() as trans:
         ^^^^^^^^^^^^^^^^^^
  File "/home/sfullerton24/python/lib/python3.11/site-packages/sqlalchemy/engine/base.py", line 867, in begin
    raise exc.InvalidRequestError(
sqlalchemy.exc.InvalidRequestError: This connection has already initialized a SQLAlchemy Transaction() object via begin() or autobegin; can't call begin() here unless rollback() or commit() is called first.
2024-04-23 13:56:49.224188 data/geoTwitter21-01-08.zip
2024-04-23 13:56:50.282267 insert_tweets i= 0
Traceback (most recent call last):
  File "/home/sfullerton24/twitter_postgres_parallel/load_tweets_batch.py", line 432, in <module>
    insert_tweets(connection,tweets,args.batch_size)
  File "/home/sfullerton24/twitter_postgres_parallel/load_tweets_batch.py", line 149, in insert_tweets
    _insert_tweets(connection, tweet_batch)
  File "/home/sfullerton24/twitter_postgres_parallel/load_tweets_batch.py", line 368, in _insert_tweets
    with connection.begin() as trans:
         ^^^^^^^^^^^^^^^^^^
  File "/home/sfullerton24/python/lib/python3.11/site-packages/sqlalchemy/engine/base.py", line 867, in begin
    raise exc.InvalidRequestError(
sqlalchemy.exc.InvalidRequestError: This connection has already initialized a SQLAlchemy Transaction() object via begin() or autobegin; can't call begin() here unless rollback() or commit() is called first.
2024-04-23 13:56:49.219823 data/geoTwitter21-01-04.zip
2024-04-23 13:56:50.313527 insert_tweets i= 0
Traceback (most recent call last):
  File "/home/sfullerton24/twitter_postgres_parallel/load_tweets_batch.py", line 432, in <module>
    insert_tweets(connection,tweets,args.batch_size)
  File "/home/sfullerton24/twitter_postgres_parallel/load_tweets_batch.py", line 149, in insert_tweets
    _insert_tweets(connection, tweet_batch)
  File "/home/sfullerton24/twitter_postgres_parallel/load_tweets_batch.py", line 368, in _insert_tweets
    with connection.begin() as trans:
         ^^^^^^^^^^^^^^^^^^
  File "/home/sfullerton24/python/lib/python3.11/site-packages/sqlalchemy/engine/base.py", line 867, in begin
    raise exc.InvalidRequestError(
sqlalchemy.exc.InvalidRequestError: This connection has already initialized a SQLAlchemy Transaction() object via begin() or autobegin; can't call begin() here unless rollback() or commit() is called first.
2024-04-23 13:56:49.230271 data/geoTwitter21-01-03.zip
2024-04-23 13:56:50.314553 insert_tweets i= 0
Traceback (most recent call last):
  File "/home/sfullerton24/twitter_postgres_parallel/load_tweets_batch.py", line 432, in <module>
    insert_tweets(connection,tweets,args.batch_size)
  File "/home/sfullerton24/twitter_postgres_parallel/load_tweets_batch.py", line 149, in insert_tweets
    _insert_tweets(connection, tweet_batch)
  File "/home/sfullerton24/twitter_postgres_parallel/load_tweets_batch.py", line 368, in _insert_tweets
    with connection.begin() as trans:
         ^^^^^^^^^^^^^^^^^^
  File "/home/sfullerton24/python/lib/python3.11/site-packages/sqlalchemy/engine/base.py", line 867, in begin
    raise exc.InvalidRequestError(
sqlalchemy.exc.InvalidRequestError: This connection has already initialized a SQLAlchemy Transaction() object via begin() or autobegin; can't call begin() here unless rollback() or commit() is called first.
2024-04-23 13:56:49.269900 data/geoTwitter21-01-02.zip
2024-04-23 13:56:50.339353 insert_tweets i= 0
Traceback (most recent call last):
  File "/home/sfullerton24/twitter_postgres_parallel/load_tweets_batch.py", line 432, in <module>
    insert_tweets(connection,tweets,args.batch_size)
  File "/home/sfullerton24/twitter_postgres_parallel/load_tweets_batch.py", line 149, in insert_tweets
    _insert_tweets(connection, tweet_batch)
  File "/home/sfullerton24/twitter_postgres_parallel/load_tweets_batch.py", line 368, in _insert_tweets
    with connection.begin() as trans:
         ^^^^^^^^^^^^^^^^^^
  File "/home/sfullerton24/python/lib/python3.11/site-packages/sqlalchemy/engine/base.py", line 867, in begin
    raise exc.InvalidRequestError(
sqlalchemy.exc.InvalidRequestError: This connection has already initialized a SQLAlchemy Transaction() object via begin() or autobegin; can't call begin() here unless rollback() or commit() is called first.
2024-04-23 13:56:49.224321 data/geoTwitter21-01-07.zip
2024-04-23 13:56:50.333655 insert_tweets i= 0
Traceback (most recent call last):
  File "/home/sfullerton24/twitter_postgres_parallel/load_tweets_batch.py", line 432, in <module>
    insert_tweets(connection,tweets,args.batch_size)
  File "/home/sfullerton24/twitter_postgres_parallel/load_tweets_batch.py", line 149, in insert_tweets
    _insert_tweets(connection, tweet_batch)
  File "/home/sfullerton24/twitter_postgres_parallel/load_tweets_batch.py", line 368, in _insert_tweets
    with connection.begin() as trans:
         ^^^^^^^^^^^^^^^^^^
  File "/home/sfullerton24/python/lib/python3.11/site-packages/sqlalchemy/engine/base.py", line 867, in begin
    raise exc.InvalidRequestError(
sqlalchemy.exc.InvalidRequestError: This connection has already initialized a SQLAlchemy Transaction() object via begin() or autobegin; can't call begin() here unless rollback() or commit() is called first.
2024-04-23 13:56:49.269973 data/geoTwitter21-01-09.zip
2024-04-23 13:56:50.361053 insert_tweets i= 0
Traceback (most recent call last):
  File "/home/sfullerton24/twitter_postgres_parallel/load_tweets_batch.py", line 432, in <module>
    insert_tweets(connection,tweets,args.batch_size)
  File "/home/sfullerton24/twitter_postgres_parallel/load_tweets_batch.py", line 149, in insert_tweets
    _insert_tweets(connection, tweet_batch)
  File "/home/sfullerton24/twitter_postgres_parallel/load_tweets_batch.py", line 368, in _insert_tweets
    with connection.begin() as trans:
         ^^^^^^^^^^^^^^^^^^
  File "/home/sfullerton24/python/lib/python3.11/site-packages/sqlalchemy/engine/base.py", line 867, in begin
    raise exc.InvalidRequestError(
sqlalchemy.exc.InvalidRequestError: This connection has already initialized a SQLAlchemy Transaction() object via begin() or autobegin; can't call begin() here unless rollback() or commit() is called first.
2024-04-23 13:56:49.267040 data/geoTwitter21-01-05.zip
2024-04-23 13:56:50.391785 insert_tweets i= 0
Traceback (most recent call last):
  File "/home/sfullerton24/twitter_postgres_parallel/load_tweets_batch.py", line 432, in <module>
    insert_tweets(connection,tweets,args.batch_size)
  File "/home/sfullerton24/twitter_postgres_parallel/load_tweets_batch.py", line 149, in insert_tweets
    _insert_tweets(connection, tweet_batch)
  File "/home/sfullerton24/twitter_postgres_parallel/load_tweets_batch.py", line 368, in _insert_tweets
    with connection.begin() as trans:
         ^^^^^^^^^^^^^^^^^^
  File "/home/sfullerton24/python/lib/python3.11/site-packages/sqlalchemy/engine/base.py", line 867, in begin
    raise exc.InvalidRequestError(
sqlalchemy.exc.InvalidRequestError: This connection has already initialized a SQLAlchemy Transaction() object via begin() or autobegin; can't call begin() here unless rollback() or commit() is called first.
2024-04-23 13:56:49.267650 data/geoTwitter21-01-10.zip
2024-04-23 13:56:50.379769 insert_tweets i= 0
Traceback (most recent call last):
  File "/home/sfullerton24/twitter_postgres_parallel/load_tweets_batch.py", line 432, in <module>
    insert_tweets(connection,tweets,args.batch_size)
  File "/home/sfullerton24/twitter_postgres_parallel/load_tweets_batch.py", line 149, in insert_tweets
    _insert_tweets(connection, tweet_batch)
  File "/home/sfullerton24/twitter_postgres_parallel/load_tweets_batch.py", line 368, in _insert_tweets
    with connection.begin() as trans:
         ^^^^^^^^^^^^^^^^^^
  File "/home/sfullerton24/python/lib/python3.11/site-packages/sqlalchemy/engine/base.py", line 867, in begin
    raise exc.InvalidRequestError(
sqlalchemy.exc.InvalidRequestError: This connection has already initialized a SQLAlchemy Transaction() object via begin() or autobegin; can't call begin() here unless rollback() or commit() is called first.
2024-04-23 13:56:49.351877 data/geoTwitter21-01-06.zip
2024-04-23 13:56:50.584898 insert_tweets i= 0
Traceback (most recent call last):
  File "/home/sfullerton24/twitter_postgres_parallel/load_tweets_batch.py", line 432, in <module>
    insert_tweets(connection,tweets,args.batch_size)
  File "/home/sfullerton24/twitter_postgres_parallel/load_tweets_batch.py", line 149, in insert_tweets
    _insert_tweets(connection, tweet_batch)
  File "/home/sfullerton24/twitter_postgres_parallel/load_tweets_batch.py", line 368, in _insert_tweets
    with connection.begin() as trans:
         ^^^^^^^^^^^^^^^^^^
  File "/home/sfullerton24/python/lib/python3.11/site-packages/sqlalchemy/engine/base.py", line 867, in begin
    raise exc.InvalidRequestError(
sqlalchemy.exc.InvalidRequestError: This connection has already initialized a SQLAlchemy Transaction() object via begin() or autobegin; can't call begin() here unless rollback() or commit() is called first.
Command exited with non-zero status 10
19.42user 1.61system 0:02.74elapsed 767%CPU (0avgtext+0avgdata 204172maxresident)k
272inputs+3248outputs (0major+488265minor)pagefaults 0swaps
================================================================================
load pg_denormalized
================================================================================
COPY 10000
COPY 10000
COPY 10000
COPY 10000
COPY 10000
COPY 10000
COPY 10000
COPY 10000
COPY 10000
COPY 10000
5.55user 1.49system 0:05.46elapsed 129%CPU (0avgtext+0avgdata 17732maxresident)k
109064inputs+2728outputs (5major+52732minor)pagefaults 0swaps
================================================================================
load pg_normalized
================================================================================
2024-04-23 21:18:53.396227 data/geoTwitter21-01-06.zip
Traceback (most recent call last):
  File "/home/sfullerton24/python/lib/python3.11/site-packages/sqlalchemy/engine/base.py", line 1970, in _exec_single_context
    self.dialect.do_execute(
  File "/home/sfullerton24/python/lib/python3.11/site-packages/sqlalchemy/engine/default.py", line 924, in do_execute
    cursor.execute(statement, parameters)
psycopg2.errors.UndefinedColumn: column "id_urls" of relation "users" does not exist
LINE 3:             (id_users, created_at, updated_at, id_urls, frie...
                                                       ^


The above exception was the direct cause of the following exception:

Traceback (most recent call last):
  File "/home/sfullerton24/twitter_postgres_parallel/load_tweets.py", line 384, in <module>
    insert_tweet(connection,tweet)
  File "/home/sfullerton24/twitter_postgres_parallel/load_tweets.py", line 125, in insert_tweet
    res = connection.execute(sql, {
          ^^^^^^^^^^^^^^^^^^^^^^^^^
  File "/home/sfullerton24/python/lib/python3.11/site-packages/sqlalchemy/engine/base.py", line 1421, in execute
    return meth(
           ^^^^^
  File "/home/sfullerton24/python/lib/python3.11/site-packages/sqlalchemy/sql/elements.py", line 514, in _execute_on_connection
    return connection._execute_clauseelement(
           ^^^^^^^^^^^^^^^^^^^^^^^^^^^^^^^^^^
  File "/home/sfullerton24/python/lib/python3.11/site-packages/sqlalchemy/engine/base.py", line 1643, in _execute_clauseelement
    ret = self._execute_context(
          ^^^^^^^^^^^^^^^^^^^^^^
  File "/home/sfullerton24/python/lib/python3.11/site-packages/sqlalchemy/engine/base.py", line 1849, in _execute_context
    return self._exec_single_context(
           ^^^^^^^^^^^^^^^^^^^^^^^^^^
  File "/home/sfullerton24/python/lib/python3.11/site-packages/sqlalchemy/engine/base.py", line 1989, in _exec_single_context
    self._handle_dbapi_exception(
  File "/home/sfullerton24/python/lib/python3.11/site-packages/sqlalchemy/engine/base.py", line 2356, in _handle_dbapi_exception
    raise sqlalchemy_exception.with_traceback(exc_info[2]) from e
  File "/home/sfullerton24/python/lib/python3.11/site-packages/sqlalchemy/engine/base.py", line 1970, in _exec_single_context
    self.dialect.do_execute(
  File "/home/sfullerton24/python/lib/python3.11/site-packages/sqlalchemy/engine/default.py", line 924, in do_execute
    cursor.execute(statement, parameters)
sqlalchemy.exc.ProgrammingError: (psycopg2.errors.UndefinedColumn) column "id_urls" of relation "users" does not exist
LINE 3:             (id_users, created_at, updated_at, id_urls, frie...
                                                       ^

[SQL: 
            INSERT INTO users
            (id_users, created_at, updated_at, id_urls, friends_count, listed_count, favourites_count, statuses_count, protected, verified, screen_name, name, location, description) 
            VALUES
            (%(id_users)s, %(created_at)s, %(updated_at)s, %(id_urls)s, %(friends_count)s, %(listed_count)s, %(favourites_count)s, %(statuses_count)s, %(protected)s, %(verified)s, %(screen_name)s, %(name)s, %(location)s, %(description)s)
            ON CONFLICT DO NOTHING
            returning id_users
                ]
[parameters: {'id_users': 751088707734831104, 'created_at': 'Thu Jul 07 16:21:17 +0000 2016', 'updated_at': 'Wed Jan 06 00:00:00 +0000 2021', 'id_urls': None, 'friends_count': 1253, 'listed_count': 0, 'favourites_count': 449, 'statuses_count': 827, 'protected': False, 'verified': False, 'screen_name': 'FatsLamuntuKyrd', 'name': 'Martin Mosehle', 'location': 'Polokwane', 'description': 'MC| Performing Artist| Radio Presenter @RadioTurf| Sema2020 Award Winner.\nbooking: fatslamuntukyrd@gmail.com or call: 0767289445'}]
(Background on this error at: https://sqlalche.me/e/20/f405)
2024-04-23 21:18:53.430610 data/geoTwitter21-01-07.zip
Traceback (most recent call last):
  File "/home/sfullerton24/python/lib/python3.11/site-packages/sqlalchemy/engine/base.py", line 1970, in _exec_single_context
    self.dialect.do_execute(
  File "/home/sfullerton24/python/lib/python3.11/site-packages/sqlalchemy/engine/default.py", line 924, in do_execute
    cursor.execute(statement, parameters)
psycopg2.errors.UndefinedTable: relation "urls" does not exist
LINE 2:     insert into urls 
                        ^


The above exception was the direct cause of the following exception:

Traceback (most recent call last):
  File "/home/sfullerton24/twitter_postgres_parallel/load_tweets.py", line 384, in <module>
    insert_tweet(connection,tweet)
  File "/home/sfullerton24/twitter_postgres_parallel/load_tweets.py", line 113, in insert_tweet
    user_id_urls = get_id_urls(tweet['user']['url'], connection)
                   ^^^^^^^^^^^^^^^^^^^^^^^^^^^^^^^^^^^^^^^^^^^^^
  File "/home/sfullerton24/twitter_postgres_parallel/load_tweets.py", line 58, in get_id_urls
    res = connection.execute(sql,{'url':url}).first()
          ^^^^^^^^^^^^^^^^^^^^^^^^^^^^^^^^^^^
  File "/home/sfullerton24/python/lib/python3.11/site-packages/sqlalchemy/engine/base.py", line 1421, in execute
    return meth(
           ^^^^^
  File "/home/sfullerton24/python/lib/python3.11/site-packages/sqlalchemy/sql/elements.py", line 514, in _execute_on_connection
    return connection._execute_clauseelement(
           ^^^^^^^^^^^^^^^^^^^^^^^^^^^^^^^^^^
  File "/home/sfullerton24/python/lib/python3.11/site-packages/sqlalchemy/engine/base.py", line 1643, in _execute_clauseelement
    ret = self._execute_context(
          ^^^^^^^^^^^^^^^^^^^^^^
  File "/home/sfullerton24/python/lib/python3.11/site-packages/sqlalchemy/engine/base.py", line 1849, in _execute_context
    return self._exec_single_context(
           ^^^^^^^^^^^^^^^^^^^^^^^^^^
  File "/home/sfullerton24/python/lib/python3.11/site-packages/sqlalchemy/engine/base.py", line 1989, in _exec_single_context
    self._handle_dbapi_exception(
  File "/home/sfullerton24/python/lib/python3.11/site-packages/sqlalchemy/engine/base.py", line 2356, in _handle_dbapi_exception
    raise sqlalchemy_exception.with_traceback(exc_info[2]) from e
  File "/home/sfullerton24/python/lib/python3.11/site-packages/sqlalchemy/engine/base.py", line 1970, in _exec_single_context
    self.dialect.do_execute(
  File "/home/sfullerton24/python/lib/python3.11/site-packages/sqlalchemy/engine/default.py", line 924, in do_execute
    cursor.execute(statement, parameters)
sqlalchemy.exc.ProgrammingError: (psycopg2.errors.UndefinedTable) relation "urls" does not exist
LINE 2:     insert into urls 
                        ^

[SQL: 
    insert into urls 
        (url)
        values
        (%(url)s)
    on conflict do nothing
    returning id_urls
    ;
    ]
[parameters: {'url': 'http://therossowenshow.com'}]
(Background on this error at: https://sqlalche.me/e/20/f405)
2024-04-23 21:18:53.431886 data/geoTwitter21-01-02.zip
Traceback (most recent call last):
  File "/home/sfullerton24/python/lib/python3.11/site-packages/sqlalchemy/engine/base.py", line 1970, in _exec_single_context
    self.dialect.do_execute(
  File "/home/sfullerton24/python/lib/python3.11/site-packages/sqlalchemy/engine/default.py", line 924, in do_execute
    cursor.execute(statement, parameters)
psycopg2.errors.UndefinedColumn: column "id_urls" of relation "users" does not exist
LINE 3:             (id_users, created_at, updated_at, id_urls, frie...
                                                       ^


The above exception was the direct cause of the following exception:

Traceback (most recent call last):
  File "/home/sfullerton24/twitter_postgres_parallel/load_tweets.py", line 384, in <module>
    insert_tweet(connection,tweet)
  File "/home/sfullerton24/twitter_postgres_parallel/load_tweets.py", line 125, in insert_tweet
    res = connection.execute(sql, {
          ^^^^^^^^^^^^^^^^^^^^^^^^^
  File "/home/sfullerton24/python/lib/python3.11/site-packages/sqlalchemy/engine/base.py", line 1421, in execute
    return meth(
           ^^^^^
  File "/home/sfullerton24/python/lib/python3.11/site-packages/sqlalchemy/sql/elements.py", line 514, in _execute_on_connection
    return connection._execute_clauseelement(
           ^^^^^^^^^^^^^^^^^^^^^^^^^^^^^^^^^^
  File "/home/sfullerton24/python/lib/python3.11/site-packages/sqlalchemy/engine/base.py", line 1643, in _execute_clauseelement
    ret = self._execute_context(
          ^^^^^^^^^^^^^^^^^^^^^^
  File "/home/sfullerton24/python/lib/python3.11/site-packages/sqlalchemy/engine/base.py", line 1849, in _execute_context
    return self._exec_single_context(
           ^^^^^^^^^^^^^^^^^^^^^^^^^^
  File "/home/sfullerton24/python/lib/python3.11/site-packages/sqlalchemy/engine/base.py", line 1989, in _exec_single_context
    self._handle_dbapi_exception(
  File "/home/sfullerton24/python/lib/python3.11/site-packages/sqlalchemy/engine/base.py", line 2356, in _handle_dbapi_exception
    raise sqlalchemy_exception.with_traceback(exc_info[2]) from e
  File "/home/sfullerton24/python/lib/python3.11/site-packages/sqlalchemy/engine/base.py", line 1970, in _exec_single_context
    self.dialect.do_execute(
  File "/home/sfullerton24/python/lib/python3.11/site-packages/sqlalchemy/engine/default.py", line 924, in do_execute
    cursor.execute(statement, parameters)
sqlalchemy.exc.ProgrammingError: (psycopg2.errors.UndefinedColumn) column "id_urls" of relation "users" does not exist
LINE 3:             (id_users, created_at, updated_at, id_urls, frie...
                                                       ^

[SQL: 
            INSERT INTO users
            (id_users, created_at, updated_at, id_urls, friends_count, listed_count, favourites_count, statuses_count, protected, verified, screen_name, name, location, description) 
            VALUES
            (%(id_users)s, %(created_at)s, %(updated_at)s, %(id_urls)s, %(friends_count)s, %(listed_count)s, %(favourites_count)s, %(statuses_count)s, %(protected)s, %(verified)s, %(screen_name)s, %(name)s, %(location)s, %(description)s)
            ON CONFLICT DO NOTHING
            returning id_users
                ]
[parameters: {'id_users': 2433927221, 'created_at': 'Mon Mar 24 19:13:19 +0000 2014', 'updated_at': 'Sat Jan 02 00:00:00 +0000 2021', 'id_urls': None, 'friends_count': 313, 'listed_count': 0, 'favourites_count': 36059, 'statuses_count': 4650, 'protected': False, 'verified': False, 'screen_name': 'hisham5632', 'name': 'هشام حميد', 'location': 'ينبع, المملكة العربية السعودية', 'description': '\u200f\u200f\u200f\u200f.أهوى الأدب العربي\nكل ما تجده هنا اقتباسات أعجبت بها\nاللهم اجعلها شاهد لي لا علي'}]
(Background on this error at: https://sqlalche.me/e/20/f405)
2024-04-23 21:18:53.442277 data/geoTwitter21-01-04.zip
Traceback (most recent call last):
  File "/home/sfullerton24/python/lib/python3.11/site-packages/sqlalchemy/engine/base.py", line 1970, in _exec_single_context
    self.dialect.do_execute(
  File "/home/sfullerton24/python/lib/python3.11/site-packages/sqlalchemy/engine/default.py", line 924, in do_execute
    cursor.execute(statement, parameters)
psycopg2.errors.UndefinedTable: relation "urls" does not exist
LINE 2:     insert into urls 
                        ^


The above exception was the direct cause of the following exception:

Traceback (most recent call last):
  File "/home/sfullerton24/twitter_postgres_parallel/load_tweets.py", line 384, in <module>
    insert_tweet(connection,tweet)
  File "/home/sfullerton24/twitter_postgres_parallel/load_tweets.py", line 113, in insert_tweet
    user_id_urls = get_id_urls(tweet['user']['url'], connection)
                   ^^^^^^^^^^^^^^^^^^^^^^^^^^^^^^^^^^^^^^^^^^^^^
  File "/home/sfullerton24/twitter_postgres_parallel/load_tweets.py", line 58, in get_id_urls
    res = connection.execute(sql,{'url':url}).first()
          ^^^^^^^^^^^^^^^^^^^^^^^^^^^^^^^^^^^
  File "/home/sfullerton24/python/lib/python3.11/site-packages/sqlalchemy/engine/base.py", line 1421, in execute
    return meth(
           ^^^^^
  File "/home/sfullerton24/python/lib/python3.11/site-packages/sqlalchemy/sql/elements.py", line 514, in _execute_on_connection
    return connection._execute_clauseelement(
           ^^^^^^^^^^^^^^^^^^^^^^^^^^^^^^^^^^
  File "/home/sfullerton24/python/lib/python3.11/site-packages/sqlalchemy/engine/base.py", line 1643, in _execute_clauseelement
    ret = self._execute_context(
          ^^^^^^^^^^^^^^^^^^^^^^
  File "/home/sfullerton24/python/lib/python3.11/site-packages/sqlalchemy/engine/base.py", line 1849, in _execute_context
    return self._exec_single_context(
           ^^^^^^^^^^^^^^^^^^^^^^^^^^
  File "/home/sfullerton24/python/lib/python3.11/site-packages/sqlalchemy/engine/base.py", line 1989, in _exec_single_context
    self._handle_dbapi_exception(
  File "/home/sfullerton24/python/lib/python3.11/site-packages/sqlalchemy/engine/base.py", line 2356, in _handle_dbapi_exception
    raise sqlalchemy_exception.with_traceback(exc_info[2]) from e
  File "/home/sfullerton24/python/lib/python3.11/site-packages/sqlalchemy/engine/base.py", line 1970, in _exec_single_context
    self.dialect.do_execute(
  File "/home/sfullerton24/python/lib/python3.11/site-packages/sqlalchemy/engine/default.py", line 924, in do_execute
    cursor.execute(statement, parameters)
sqlalchemy.exc.ProgrammingError: (psycopg2.errors.UndefinedTable) relation "urls" does not exist
LINE 2:     insert into urls 
                        ^

[SQL: 
    insert into urls 
        (url)
        values
        (%(url)s)
    on conflict do nothing
    returning id_urls
    ;
    ]
[parameters: {'url': 'https://profcard.info/u/CdAQKXlp0XOI9EAkkIo79bnn2qw1'}]
(Background on this error at: https://sqlalche.me/e/20/f405)
2024-04-23 21:18:53.434530 data/geoTwitter21-01-08.zip
Traceback (most recent call last):
  File "/home/sfullerton24/python/lib/python3.11/site-packages/sqlalchemy/engine/base.py", line 1970, in _exec_single_context
    self.dialect.do_execute(
  File "/home/sfullerton24/python/lib/python3.11/site-packages/sqlalchemy/engine/default.py", line 924, in do_execute
    cursor.execute(statement, parameters)
psycopg2.errors.UndefinedColumn: column "id_urls" of relation "users" does not exist
LINE 3:             (id_users, created_at, updated_at, id_urls, frie...
                                                       ^


The above exception was the direct cause of the following exception:

Traceback (most recent call last):
  File "/home/sfullerton24/twitter_postgres_parallel/load_tweets.py", line 384, in <module>
    insert_tweet(connection,tweet)
  File "/home/sfullerton24/twitter_postgres_parallel/load_tweets.py", line 125, in insert_tweet
    res = connection.execute(sql, {
          ^^^^^^^^^^^^^^^^^^^^^^^^^
  File "/home/sfullerton24/python/lib/python3.11/site-packages/sqlalchemy/engine/base.py", line 1421, in execute
    return meth(
           ^^^^^
  File "/home/sfullerton24/python/lib/python3.11/site-packages/sqlalchemy/sql/elements.py", line 514, in _execute_on_connection
    return connection._execute_clauseelement(
           ^^^^^^^^^^^^^^^^^^^^^^^^^^^^^^^^^^
  File "/home/sfullerton24/python/lib/python3.11/site-packages/sqlalchemy/engine/base.py", line 1643, in _execute_clauseelement
    ret = self._execute_context(
          ^^^^^^^^^^^^^^^^^^^^^^
  File "/home/sfullerton24/python/lib/python3.11/site-packages/sqlalchemy/engine/base.py", line 1849, in _execute_context
    return self._exec_single_context(
           ^^^^^^^^^^^^^^^^^^^^^^^^^^
  File "/home/sfullerton24/python/lib/python3.11/site-packages/sqlalchemy/engine/base.py", line 1989, in _exec_single_context
    self._handle_dbapi_exception(
  File "/home/sfullerton24/python/lib/python3.11/site-packages/sqlalchemy/engine/base.py", line 2356, in _handle_dbapi_exception
    raise sqlalchemy_exception.with_traceback(exc_info[2]) from e
  File "/home/sfullerton24/python/lib/python3.11/site-packages/sqlalchemy/engine/base.py", line 1970, in _exec_single_context
    self.dialect.do_execute(
  File "/home/sfullerton24/python/lib/python3.11/site-packages/sqlalchemy/engine/default.py", line 924, in do_execute
    cursor.execute(statement, parameters)
sqlalchemy.exc.ProgrammingError: (psycopg2.errors.UndefinedColumn) column "id_urls" of relation "users" does not exist
LINE 3:             (id_users, created_at, updated_at, id_urls, frie...
                                                       ^

[SQL: 
            INSERT INTO users
            (id_users, created_at, updated_at, id_urls, friends_count, listed_count, favourites_count, statuses_count, protected, verified, screen_name, name, location, description) 
            VALUES
            (%(id_users)s, %(created_at)s, %(updated_at)s, %(id_urls)s, %(friends_count)s, %(listed_count)s, %(favourites_count)s, %(statuses_count)s, %(protected)s, %(verified)s, %(screen_name)s, %(name)s, %(location)s, %(description)s)
            ON CONFLICT DO NOTHING
            returning id_users
                ]
[parameters: {'id_users': 489724297, 'created_at': 'Sat Feb 11 20:33:17 +0000 2012', 'updated_at': 'Fri Jan 08 00:00:00 +0000 2021', 'id_urls': None, 'friends_count': 638, 'listed_count': 7, 'favourites_count': 16295, 'statuses_count': 26495, 'protected': False, 'verified': False, 'screen_name': 'one_n_emillion_', 'name': 'em', 'location': 'tx', 'description': 'gemini pescatarian'}]
(Background on this error at: https://sqlalche.me/e/20/f405)
2024-04-23 21:18:53.432494 data/geoTwitter21-01-10.zip
Traceback (most recent call last):
  File "/home/sfullerton24/python/lib/python3.11/site-packages/sqlalchemy/engine/base.py", line 1970, in _exec_single_context
    self.dialect.do_execute(
  File "/home/sfullerton24/python/lib/python3.11/site-packages/sqlalchemy/engine/default.py", line 924, in do_execute
    cursor.execute(statement, parameters)
psycopg2.errors.UndefinedColumn: column "id_urls" of relation "users" does not exist
LINE 3:             (id_users, created_at, updated_at, id_urls, frie...
                                                       ^


The above exception was the direct cause of the following exception:

Traceback (most recent call last):
  File "/home/sfullerton24/twitter_postgres_parallel/load_tweets.py", line 384, in <module>
    insert_tweet(connection,tweet)
  File "/home/sfullerton24/twitter_postgres_parallel/load_tweets.py", line 125, in insert_tweet
    res = connection.execute(sql, {
          ^^^^^^^^^^^^^^^^^^^^^^^^^
  File "/home/sfullerton24/python/lib/python3.11/site-packages/sqlalchemy/engine/base.py", line 1421, in execute
    return meth(
           ^^^^^
  File "/home/sfullerton24/python/lib/python3.11/site-packages/sqlalchemy/sql/elements.py", line 514, in _execute_on_connection
    return connection._execute_clauseelement(
           ^^^^^^^^^^^^^^^^^^^^^^^^^^^^^^^^^^
  File "/home/sfullerton24/python/lib/python3.11/site-packages/sqlalchemy/engine/base.py", line 1643, in _execute_clauseelement
    ret = self._execute_context(
          ^^^^^^^^^^^^^^^^^^^^^^
  File "/home/sfullerton24/python/lib/python3.11/site-packages/sqlalchemy/engine/base.py", line 1849, in _execute_context
    return self._exec_single_context(
           ^^^^^^^^^^^^^^^^^^^^^^^^^^
  File "/home/sfullerton24/python/lib/python3.11/site-packages/sqlalchemy/engine/base.py", line 1989, in _exec_single_context
    self._handle_dbapi_exception(
  File "/home/sfullerton24/python/lib/python3.11/site-packages/sqlalchemy/engine/base.py", line 2356, in _handle_dbapi_exception
    raise sqlalchemy_exception.with_traceback(exc_info[2]) from e
  File "/home/sfullerton24/python/lib/python3.11/site-packages/sqlalchemy/engine/base.py", line 1970, in _exec_single_context
    self.dialect.do_execute(
  File "/home/sfullerton24/python/lib/python3.11/site-packages/sqlalchemy/engine/default.py", line 924, in do_execute
    cursor.execute(statement, parameters)
sqlalchemy.exc.ProgrammingError: (psycopg2.errors.UndefinedColumn) column "id_urls" of relation "users" does not exist
LINE 3:             (id_users, created_at, updated_at, id_urls, frie...
                                                       ^

[SQL: 
            INSERT INTO users
            (id_users, created_at, updated_at, id_urls, friends_count, listed_count, favourites_count, statuses_count, protected, verified, screen_name, name, location, description) 
            VALUES
            (%(id_users)s, %(created_at)s, %(updated_at)s, %(id_urls)s, %(friends_count)s, %(listed_count)s, %(favourites_count)s, %(statuses_count)s, %(protected)s, %(verified)s, %(screen_name)s, %(name)s, %(location)s, %(description)s)
            ON CONFLICT DO NOTHING
            returning id_users
                ]
[parameters: {'id_users': 1122211946516963328, 'created_at': 'Sat Apr 27 18:52:32 +0000 2019', 'updated_at': 'Sun Jan 10 00:00:00 +0000 2021', 'id_urls': None, 'friends_count': 910, 'listed_count': 0, 'favourites_count': 11592, 'statuses_count': 6233, 'protected': False, 'verified': False, 'screen_name': 'PaulieA93', 'name': 'Paul', 'location': '🇨🇦', 'description': 'Huge supporter of #Leafsforever #GOPACKGO #Sporting_CP #Selecaoportugal #Ticats #Metallica 🇨🇦🇵🇹'}]
(Background on this error at: https://sqlalche.me/e/20/f405)
2024-04-23 21:18:53.432968 data/geoTwitter21-01-01.zip
Traceback (most recent call last):
  File "/home/sfullerton24/python/lib/python3.11/site-packages/sqlalchemy/engine/base.py", line 1970, in _exec_single_context
    self.dialect.do_execute(
  File "/home/sfullerton24/python/lib/python3.11/site-packages/sqlalchemy/engine/default.py", line 924, in do_execute
    cursor.execute(statement, parameters)
psycopg2.errors.UndefinedColumn: column "id_urls" of relation "users" does not exist
LINE 3:             (id_users, created_at, updated_at, id_urls, frie...
                                                       ^


The above exception was the direct cause of the following exception:

Traceback (most recent call last):
  File "/home/sfullerton24/twitter_postgres_parallel/load_tweets.py", line 384, in <module>
    insert_tweet(connection,tweet)
  File "/home/sfullerton24/twitter_postgres_parallel/load_tweets.py", line 125, in insert_tweet
    res = connection.execute(sql, {
          ^^^^^^^^^^^^^^^^^^^^^^^^^
  File "/home/sfullerton24/python/lib/python3.11/site-packages/sqlalchemy/engine/base.py", line 1421, in execute
    return meth(
           ^^^^^
  File "/home/sfullerton24/python/lib/python3.11/site-packages/sqlalchemy/sql/elements.py", line 514, in _execute_on_connection
    return connection._execute_clauseelement(
           ^^^^^^^^^^^^^^^^^^^^^^^^^^^^^^^^^^
  File "/home/sfullerton24/python/lib/python3.11/site-packages/sqlalchemy/engine/base.py", line 1643, in _execute_clauseelement
    ret = self._execute_context(
          ^^^^^^^^^^^^^^^^^^^^^^
  File "/home/sfullerton24/python/lib/python3.11/site-packages/sqlalchemy/engine/base.py", line 1849, in _execute_context
    return self._exec_single_context(
           ^^^^^^^^^^^^^^^^^^^^^^^^^^
  File "/home/sfullerton24/python/lib/python3.11/site-packages/sqlalchemy/engine/base.py", line 1989, in _exec_single_context
    self._handle_dbapi_exception(
  File "/home/sfullerton24/python/lib/python3.11/site-packages/sqlalchemy/engine/base.py", line 2356, in _handle_dbapi_exception
    raise sqlalchemy_exception.with_traceback(exc_info[2]) from e
  File "/home/sfullerton24/python/lib/python3.11/site-packages/sqlalchemy/engine/base.py", line 1970, in _exec_single_context
    self.dialect.do_execute(
  File "/home/sfullerton24/python/lib/python3.11/site-packages/sqlalchemy/engine/default.py", line 924, in do_execute
    cursor.execute(statement, parameters)
sqlalchemy.exc.ProgrammingError: (psycopg2.errors.UndefinedColumn) column "id_urls" of relation "users" does not exist
LINE 3:             (id_users, created_at, updated_at, id_urls, frie...
                                                       ^

[SQL: 
            INSERT INTO users
            (id_users, created_at, updated_at, id_urls, friends_count, listed_count, favourites_count, statuses_count, protected, verified, screen_name, name, location, description) 
            VALUES
            (%(id_users)s, %(created_at)s, %(updated_at)s, %(id_urls)s, %(friends_count)s, %(listed_count)s, %(favourites_count)s, %(statuses_count)s, %(protected)s, %(verified)s, %(screen_name)s, %(name)s, %(location)s, %(description)s)
            ON CONFLICT DO NOTHING
            returning id_users
                ]
[parameters: {'id_users': 41278525, 'created_at': 'Wed May 20 02:42:09 +0000 2009', 'updated_at': 'Fri Jan 01 00:00:00 +0000 2021', 'id_urls': None, 'friends_count': 1377, 'listed_count': 17, 'favourites_count': 132200, 'statuses_count': 76452, 'protected': False, 'verified': False, 'screen_name': 'Thalassatx', 'name': 'Linda Tom', 'location': 'Euless, TX', 'description': 'University of Arkansas alum, Movie fan. Marvel fanatic. Former Republican voter who now votes blue to save lives. Gun owner who believes in sensible gun laws.'}]
(Background on this error at: https://sqlalche.me/e/20/f405)
2024-04-23 21:18:53.433055 data/geoTwitter21-01-03.zip
Traceback (most recent call last):
  File "/home/sfullerton24/python/lib/python3.11/site-packages/sqlalchemy/engine/base.py", line 1970, in _exec_single_context
    self.dialect.do_execute(
  File "/home/sfullerton24/python/lib/python3.11/site-packages/sqlalchemy/engine/default.py", line 924, in do_execute
    cursor.execute(statement, parameters)
psycopg2.errors.UndefinedColumn: column "id_urls" of relation "users" does not exist
LINE 3:             (id_users, created_at, updated_at, id_urls, frie...
                                                       ^


The above exception was the direct cause of the following exception:

Traceback (most recent call last):
  File "/home/sfullerton24/twitter_postgres_parallel/load_tweets.py", line 384, in <module>
    insert_tweet(connection,tweet)
  File "/home/sfullerton24/twitter_postgres_parallel/load_tweets.py", line 125, in insert_tweet
    res = connection.execute(sql, {
          ^^^^^^^^^^^^^^^^^^^^^^^^^
  File "/home/sfullerton24/python/lib/python3.11/site-packages/sqlalchemy/engine/base.py", line 1421, in execute
    return meth(
           ^^^^^
  File "/home/sfullerton24/python/lib/python3.11/site-packages/sqlalchemy/sql/elements.py", line 514, in _execute_on_connection
    return connection._execute_clauseelement(
           ^^^^^^^^^^^^^^^^^^^^^^^^^^^^^^^^^^
  File "/home/sfullerton24/python/lib/python3.11/site-packages/sqlalchemy/engine/base.py", line 1643, in _execute_clauseelement
    ret = self._execute_context(
          ^^^^^^^^^^^^^^^^^^^^^^
  File "/home/sfullerton24/python/lib/python3.11/site-packages/sqlalchemy/engine/base.py", line 1849, in _execute_context
    return self._exec_single_context(
           ^^^^^^^^^^^^^^^^^^^^^^^^^^
  File "/home/sfullerton24/python/lib/python3.11/site-packages/sqlalchemy/engine/base.py", line 1989, in _exec_single_context
    self._handle_dbapi_exception(
  File "/home/sfullerton24/python/lib/python3.11/site-packages/sqlalchemy/engine/base.py", line 2356, in _handle_dbapi_exception
    raise sqlalchemy_exception.with_traceback(exc_info[2]) from e
  File "/home/sfullerton24/python/lib/python3.11/site-packages/sqlalchemy/engine/base.py", line 1970, in _exec_single_context
    self.dialect.do_execute(
  File "/home/sfullerton24/python/lib/python3.11/site-packages/sqlalchemy/engine/default.py", line 924, in do_execute
    cursor.execute(statement, parameters)
sqlalchemy.exc.ProgrammingError: (psycopg2.errors.UndefinedColumn) column "id_urls" of relation "users" does not exist
LINE 3:             (id_users, created_at, updated_at, id_urls, frie...
                                                       ^

[SQL: 
            INSERT INTO users
            (id_users, created_at, updated_at, id_urls, friends_count, listed_count, favourites_count, statuses_count, protected, verified, screen_name, name, location, description) 
            VALUES
            (%(id_users)s, %(created_at)s, %(updated_at)s, %(id_urls)s, %(friends_count)s, %(listed_count)s, %(favourites_count)s, %(statuses_count)s, %(protected)s, %(verified)s, %(screen_name)s, %(name)s, %(location)s, %(description)s)
            ON CONFLICT DO NOTHING
            returning id_users
                ]
[parameters: {'id_users': 2766532016, 'created_at': 'Mon Aug 25 14:28:11 +0000 2014', 'updated_at': 'Sun Jan 03 00:00:00 +0000 2021', 'id_urls': None, 'friends_count': 1360, 'listed_count': 0, 'favourites_count': 57708, 'statuses_count': 32486, 'protected': False, 'verified': False, 'screen_name': 'augelliale', 'name': 'Alemdq', 'location': 'Mar del Plata, Argentina', 'description': 'Bostero. Hincha de Peñarol basquet. Martillero y corredor. Tachero novato. Sabinero. Fotos de Mardel. Chistes malos.,Taxista 2020\n#historiasdeltaxi #soyrolando'}]
(Background on this error at: https://sqlalche.me/e/20/f405)
2024-04-23 21:18:53.439306 data/geoTwitter21-01-05.zip
Traceback (most recent call last):
  File "/home/sfullerton24/python/lib/python3.11/site-packages/sqlalchemy/engine/base.py", line 1970, in _exec_single_context
    self.dialect.do_execute(
  File "/home/sfullerton24/python/lib/python3.11/site-packages/sqlalchemy/engine/default.py", line 924, in do_execute
    cursor.execute(statement, parameters)
psycopg2.errors.UndefinedTable: relation "urls" does not exist
LINE 2:     insert into urls 
                        ^


The above exception was the direct cause of the following exception:

Traceback (most recent call last):
  File "/home/sfullerton24/twitter_postgres_parallel/load_tweets.py", line 384, in <module>
    insert_tweet(connection,tweet)
  File "/home/sfullerton24/twitter_postgres_parallel/load_tweets.py", line 113, in insert_tweet
    user_id_urls = get_id_urls(tweet['user']['url'], connection)
                   ^^^^^^^^^^^^^^^^^^^^^^^^^^^^^^^^^^^^^^^^^^^^^
  File "/home/sfullerton24/twitter_postgres_parallel/load_tweets.py", line 58, in get_id_urls
    res = connection.execute(sql,{'url':url}).first()
          ^^^^^^^^^^^^^^^^^^^^^^^^^^^^^^^^^^^
  File "/home/sfullerton24/python/lib/python3.11/site-packages/sqlalchemy/engine/base.py", line 1421, in execute
    return meth(
           ^^^^^
  File "/home/sfullerton24/python/lib/python3.11/site-packages/sqlalchemy/sql/elements.py", line 514, in _execute_on_connection
    return connection._execute_clauseelement(
           ^^^^^^^^^^^^^^^^^^^^^^^^^^^^^^^^^^
  File "/home/sfullerton24/python/lib/python3.11/site-packages/sqlalchemy/engine/base.py", line 1643, in _execute_clauseelement
    ret = self._execute_context(
          ^^^^^^^^^^^^^^^^^^^^^^
  File "/home/sfullerton24/python/lib/python3.11/site-packages/sqlalchemy/engine/base.py", line 1849, in _execute_context
    return self._exec_single_context(
           ^^^^^^^^^^^^^^^^^^^^^^^^^^
  File "/home/sfullerton24/python/lib/python3.11/site-packages/sqlalchemy/engine/base.py", line 1989, in _exec_single_context
    self._handle_dbapi_exception(
  File "/home/sfullerton24/python/lib/python3.11/site-packages/sqlalchemy/engine/base.py", line 2356, in _handle_dbapi_exception
    raise sqlalchemy_exception.with_traceback(exc_info[2]) from e
  File "/home/sfullerton24/python/lib/python3.11/site-packages/sqlalchemy/engine/base.py", line 1970, in _exec_single_context
    self.dialect.do_execute(
  File "/home/sfullerton24/python/lib/python3.11/site-packages/sqlalchemy/engine/default.py", line 924, in do_execute
    cursor.execute(statement, parameters)
sqlalchemy.exc.ProgrammingError: (psycopg2.errors.UndefinedTable) relation "urls" does not exist
LINE 2:     insert into urls 
                        ^

[SQL: 
    insert into urls 
        (url)
        values
        (%(url)s)
    on conflict do nothing
    returning id_urls
    ;
    ]
[parameters: {'url': 'http://instagram.com/anderson_bragaa'}]
(Background on this error at: https://sqlalche.me/e/20/f405)
2024-04-23 21:18:53.518615 data/geoTwitter21-01-09.zip
Traceback (most recent call last):
  File "/home/sfullerton24/python/lib/python3.11/site-packages/sqlalchemy/engine/base.py", line 1970, in _exec_single_context
    self.dialect.do_execute(
  File "/home/sfullerton24/python/lib/python3.11/site-packages/sqlalchemy/engine/default.py", line 924, in do_execute
    cursor.execute(statement, parameters)
psycopg2.errors.UndefinedColumn: column "id_urls" of relation "users" does not exist
LINE 3:             (id_users, created_at, updated_at, id_urls, frie...
                                                       ^


The above exception was the direct cause of the following exception:

Traceback (most recent call last):
  File "/home/sfullerton24/twitter_postgres_parallel/load_tweets.py", line 384, in <module>
    insert_tweet(connection,tweet)
  File "/home/sfullerton24/twitter_postgres_parallel/load_tweets.py", line 125, in insert_tweet
    res = connection.execute(sql, {
          ^^^^^^^^^^^^^^^^^^^^^^^^^
  File "/home/sfullerton24/python/lib/python3.11/site-packages/sqlalchemy/engine/base.py", line 1421, in execute
    return meth(
           ^^^^^
  File "/home/sfullerton24/python/lib/python3.11/site-packages/sqlalchemy/sql/elements.py", line 514, in _execute_on_connection
    return connection._execute_clauseelement(
           ^^^^^^^^^^^^^^^^^^^^^^^^^^^^^^^^^^
  File "/home/sfullerton24/python/lib/python3.11/site-packages/sqlalchemy/engine/base.py", line 1643, in _execute_clauseelement
    ret = self._execute_context(
          ^^^^^^^^^^^^^^^^^^^^^^
  File "/home/sfullerton24/python/lib/python3.11/site-packages/sqlalchemy/engine/base.py", line 1849, in _execute_context
    return self._exec_single_context(
           ^^^^^^^^^^^^^^^^^^^^^^^^^^
  File "/home/sfullerton24/python/lib/python3.11/site-packages/sqlalchemy/engine/base.py", line 1989, in _exec_single_context
    self._handle_dbapi_exception(
  File "/home/sfullerton24/python/lib/python3.11/site-packages/sqlalchemy/engine/base.py", line 2356, in _handle_dbapi_exception
    raise sqlalchemy_exception.with_traceback(exc_info[2]) from e
  File "/home/sfullerton24/python/lib/python3.11/site-packages/sqlalchemy/engine/base.py", line 1970, in _exec_single_context
    self.dialect.do_execute(
  File "/home/sfullerton24/python/lib/python3.11/site-packages/sqlalchemy/engine/default.py", line 924, in do_execute
    cursor.execute(statement, parameters)
sqlalchemy.exc.ProgrammingError: (psycopg2.errors.UndefinedColumn) column "id_urls" of relation "users" does not exist
LINE 3:             (id_users, created_at, updated_at, id_urls, frie...
                                                       ^

[SQL: 
            INSERT INTO users
            (id_users, created_at, updated_at, id_urls, friends_count, listed_count, favourites_count, statuses_count, protected, verified, screen_name, name, location, description) 
            VALUES
            (%(id_users)s, %(created_at)s, %(updated_at)s, %(id_urls)s, %(friends_count)s, %(listed_count)s, %(favourites_count)s, %(statuses_count)s, %(protected)s, %(verified)s, %(screen_name)s, %(name)s, %(location)s, %(description)s)
            ON CONFLICT DO NOTHING
            returning id_users
                ]
[parameters: {'id_users': 924744976248066054, 'created_at': 'Sun Oct 29 21:09:18 +0000 2017', 'updated_at': 'Sat Jan 09 00:00:00 +0000 2021', 'id_urls': None, 'friends_count': 420, 'listed_count': 0, 'favourites_count': 23132, 'statuses_count': 5687, 'protected': False, 'verified': False, 'screen_name': 'MrKrastor', 'name': '🜃євгенія🜁', 'location': 'mushroom valley', 'description': 'Tumnë talmar rahtainë nixenen umir'}]
(Background on this error at: https://sqlalche.me/e/20/f405)
Command exited with non-zero status 10
4.55user 0.54system 0:00.90elapsed 566%CPU (0avgtext+0avgdata 44820maxresident)k
48168inputs+2728outputs (73major+95595minor)pagefaults 0swaps
================================================================================
load pg_normalized_batch
================================================================================
Traceback (most recent call last):
  File "/home/sfullerton24/python/lib/python3.11/site-packages/sqlalchemy/engine/base.py", line 145, in __init__
    self._dbapi_connection = engine.raw_connection()
                             ^^^^^^^^^^^^^^^^^^^^^^^
  File "/home/sfullerton24/python/lib/python3.11/site-packages/sqlalchemy/engine/base.py", line 3303, in raw_connection
    return self.pool.connect()
           ^^^^^^^^^^^^^^^^^^^
  File "/home/sfullerton24/python/lib/python3.11/site-packages/sqlalchemy/pool/base.py", line 449, in connect
    return _ConnectionFairy._checkout(self)
           ^^^^^^^^^^^^^^^^^^^^^^^^^^^^^^^^
  File "/home/sfullerton24/python/lib/python3.11/site-packages/sqlalchemy/pool/base.py", line 1263, in _checkout
    fairy = _ConnectionRecord.checkout(pool)
            ^^^^^^^^^^^^^^^^^^^^^^^^^^^^^^^^
  File "/home/sfullerton24/python/lib/python3.11/site-packages/sqlalchemy/pool/base.py", line 712, in checkout
    rec = pool._do_get()
          ^^^^^^^^^^^^^^
  File "/home/sfullerton24/python/lib/python3.11/site-packages/sqlalchemy/pool/impl.py", line 179, in _do_get
    with util.safe_reraise():
  File "/home/sfullerton24/python/lib/python3.11/site-packages/sqlalchemy/util/langhelpers.py", line 146, in __exit__
    raise exc_value.with_traceback(exc_tb)
  File "/home/sfullerton24/python/lib/python3.11/site-packages/sqlalchemy/pool/impl.py", line 177, in _do_get
    return self._create_connection()
           ^^^^^^^^^^^^^^^^^^^^^^^^^
  File "/home/sfullerton24/python/lib/python3.11/site-packages/sqlalchemy/pool/base.py", line 390, in _create_connection
    return _ConnectionRecord(self)
           ^^^^^^^^^^^^^^^^^^^^^^^
  File "/home/sfullerton24/python/lib/python3.11/site-packages/sqlalchemy/pool/base.py", line 674, in __init__
    self.__connect()
  File "/home/sfullerton24/python/lib/python3.11/site-packages/sqlalchemy/pool/base.py", line 900, in __connect
    with util.safe_reraise():
  File "/home/sfullerton24/python/lib/python3.11/site-packages/sqlalchemy/util/langhelpers.py", line 146, in __exit__
    raise exc_value.with_traceback(exc_tb)
  File "/home/sfullerton24/python/lib/python3.11/site-packages/sqlalchemy/pool/base.py", line 896, in __connect
    self.dbapi_connection = connection = pool._invoke_creator(self)
                                         ^^^^^^^^^^^^^^^^^^^^^^^^^^
  File "/home/sfullerton24/python/lib/python3.11/site-packages/sqlalchemy/engine/create.py", line 643, in connect
    return dialect.connect(*cargs, **cparams)
           ^^^^^^^^^^^^^^^^^^^^^^^^^^^^^^^^^^
  File "/home/sfullerton24/python/lib/python3.11/site-packages/sqlalchemy/engine/default.py", line 616, in connect
    return self.loaded_dbapi.connect(*cargs, **cparams)
           ^^^^^^^^^^^^^^^^^^^^^^^^^^^^^^^^^^^^^^^^^^^^
  File "/home/sfullerton24/python/lib/python3.11/site-packages/psycopg2/__init__.py", line 122, in connect
    conn = _connect(dsn, connection_factory=connection_factory, **kwasync)
           ^^^^^^^^^^^^^^^^^^^^^^^^^^^^^^^^^^^^^^^^^^^^^^^^^^^^^^^^^^^^^^^
psycopg2.OperationalError: could not connect to server: Connection refused
	Is the server running on host "localhost" (127.0.0.1) and accepting
	TCP/IP connections on port 7449?


The above exception was the direct cause of the following exception:

Traceback (most recent call last):
  File "/home/sfullerton24/twitter_postgres_parallel/load_tweets_batch.py", line 416, in <module>
    connection = engine.connect()
                 ^^^^^^^^^^^^^^^^
  File "/home/sfullerton24/python/lib/python3.11/site-packages/sqlalchemy/engine/base.py", line 3279, in connect
    return self._connection_cls(self)
           ^^^^^^^^^^^^^^^^^^^^^^^^^^
  File "/home/sfullerton24/python/lib/python3.11/site-packages/sqlalchemy/engine/base.py", line 147, in __init__
    Connection._handle_dbapi_exception_noconnection(
  File "/home/sfullerton24/python/lib/python3.11/site-packages/sqlalchemy/engine/base.py", line 2443, in _handle_dbapi_exception_noconnection
    raise sqlalchemy_exception.with_traceback(exc_info[2]) from e
  File "/home/sfullerton24/python/lib/python3.11/site-packages/sqlalchemy/engine/base.py", line 145, in __init__
    self._dbapi_connection = engine.raw_connection()
                             ^^^^^^^^^^^^^^^^^^^^^^^
  File "/home/sfullerton24/python/lib/python3.11/site-packages/sqlalchemy/engine/base.py", line 3303, in raw_connection
    return self.pool.connect()
           ^^^^^^^^^^^^^^^^^^^
  File "/home/sfullerton24/python/lib/python3.11/site-packages/sqlalchemy/pool/base.py", line 449, in connect
    return _ConnectionFairy._checkout(self)
           ^^^^^^^^^^^^^^^^^^^^^^^^^^^^^^^^
  File "/home/sfullerton24/python/lib/python3.11/site-packages/sqlalchemy/pool/base.py", line 1263, in _checkout
    fairy = _ConnectionRecord.checkout(pool)
            ^^^^^^^^^^^^^^^^^^^^^^^^^^^^^^^^
  File "/home/sfullerton24/python/lib/python3.11/site-packages/sqlalchemy/pool/base.py", line 712, in checkout
    rec = pool._do_get()
          ^^^^^^^^^^^^^^
  File "/home/sfullerton24/python/lib/python3.11/site-packages/sqlalchemy/pool/impl.py", line 179, in _do_get
    with util.safe_reraise():
  File "/home/sfullerton24/python/lib/python3.11/site-packages/sqlalchemy/util/langhelpers.py", line 146, in __exit__
    raise exc_value.with_traceback(exc_tb)
  File "/home/sfullerton24/python/lib/python3.11/site-packages/sqlalchemy/pool/impl.py", line 177, in _do_get
    return self._create_connection()
           ^^^^^^^^^^^^^^^^^^^^^^^^^
  File "/home/sfullerton24/python/lib/python3.11/site-packages/sqlalchemy/pool/base.py", line 390, in _create_connection
    return _ConnectionRecord(self)
           ^^^^^^^^^^^^^^^^^^^^^^^
  File "/home/sfullerton24/python/lib/python3.11/site-packages/sqlalchemy/pool/base.py", line 674, in __init__
    self.__connect()
  File "/home/sfullerton24/python/lib/python3.11/site-packages/sqlalchemy/pool/base.py", line 900, in __connect
    with util.safe_reraise():
  File "/home/sfullerton24/python/lib/python3.11/site-packages/sqlalchemy/util/langhelpers.py", line 146, in __exit__
    raise exc_value.with_traceback(exc_tb)
  File "/home/sfullerton24/python/lib/python3.11/site-packages/sqlalchemy/pool/base.py", line 896, in __connect
    self.dbapi_connection = connection = pool._invoke_creator(self)
                                         ^^^^^^^^^^^^^^^^^^^^^^^^^^
  File "/home/sfullerton24/python/lib/python3.11/site-packages/sqlalchemy/engine/create.py", line 643, in connect
    return dialect.connect(*cargs, **cparams)
           ^^^^^^^^^^^^^^^^^^^^^^^^^^^^^^^^^^
  File "/home/sfullerton24/python/lib/python3.11/site-packages/sqlalchemy/engine/default.py", line 616, in connect
    return self.loaded_dbapi.connect(*cargs, **cparams)
           ^^^^^^^^^^^^^^^^^^^^^^^^^^^^^^^^^^^^^^^^^^^^
  File "/home/sfullerton24/python/lib/python3.11/site-packages/psycopg2/__init__.py", line 122, in connect
    conn = _connect(dsn, connection_factory=connection_factory, **kwasync)
           ^^^^^^^^^^^^^^^^^^^^^^^^^^^^^^^^^^^^^^^^^^^^^^^^^^^^^^^^^^^^^^^
sqlalchemy.exc.OperationalError: (psycopg2.OperationalError) could not connect to server: Connection refused
	Is the server running on host "localhost" (127.0.0.1) and accepting
	TCP/IP connections on port 7449?

(Background on this error at: https://sqlalche.me/e/20/e3q8)
Traceback (most recent call last):
  File "/home/sfullerton24/python/lib/python3.11/site-packages/sqlalchemy/engine/base.py", line 145, in __init__
    self._dbapi_connection = engine.raw_connection()
                             ^^^^^^^^^^^^^^^^^^^^^^^
  File "/home/sfullerton24/python/lib/python3.11/site-packages/sqlalchemy/engine/base.py", line 3303, in raw_connection
    return self.pool.connect()
           ^^^^^^^^^^^^^^^^^^^
  File "/home/sfullerton24/python/lib/python3.11/site-packages/sqlalchemy/pool/base.py", line 449, in connect
    return _ConnectionFairy._checkout(self)
           ^^^^^^^^^^^^^^^^^^^^^^^^^^^^^^^^
  File "/home/sfullerton24/python/lib/python3.11/site-packages/sqlalchemy/pool/base.py", line 1263, in _checkout
    fairy = _ConnectionRecord.checkout(pool)
            ^^^^^^^^^^^^^^^^^^^^^^^^^^^^^^^^
  File "/home/sfullerton24/python/lib/python3.11/site-packages/sqlalchemy/pool/base.py", line 712, in checkout
    rec = pool._do_get()
          ^^^^^^^^^^^^^^
  File "/home/sfullerton24/python/lib/python3.11/site-packages/sqlalchemy/pool/impl.py", line 179, in _do_get
    with util.safe_reraise():
  File "/home/sfullerton24/python/lib/python3.11/site-packages/sqlalchemy/util/langhelpers.py", line 146, in __exit__
    raise exc_value.with_traceback(exc_tb)
  File "/home/sfullerton24/python/lib/python3.11/site-packages/sqlalchemy/pool/impl.py", line 177, in _do_get
    return self._create_connection()
           ^^^^^^^^^^^^^^^^^^^^^^^^^
  File "/home/sfullerton24/python/lib/python3.11/site-packages/sqlalchemy/pool/base.py", line 390, in _create_connection
    return _ConnectionRecord(self)
           ^^^^^^^^^^^^^^^^^^^^^^^
  File "/home/sfullerton24/python/lib/python3.11/site-packages/sqlalchemy/pool/base.py", line 674, in __init__
    self.__connect()
  File "/home/sfullerton24/python/lib/python3.11/site-packages/sqlalchemy/pool/base.py", line 900, in __connect
    with util.safe_reraise():
  File "/home/sfullerton24/python/lib/python3.11/site-packages/sqlalchemy/util/langhelpers.py", line 146, in __exit__
    raise exc_value.with_traceback(exc_tb)
  File "/home/sfullerton24/python/lib/python3.11/site-packages/sqlalchemy/pool/base.py", line 896, in __connect
    self.dbapi_connection = connection = pool._invoke_creator(self)
                                         ^^^^^^^^^^^^^^^^^^^^^^^^^^
  File "/home/sfullerton24/python/lib/python3.11/site-packages/sqlalchemy/engine/create.py", line 643, in connect
    return dialect.connect(*cargs, **cparams)
           ^^^^^^^^^^^^^^^^^^^^^^^^^^^^^^^^^^
  File "/home/sfullerton24/python/lib/python3.11/site-packages/sqlalchemy/engine/default.py", line 616, in connect
    return self.loaded_dbapi.connect(*cargs, **cparams)
           ^^^^^^^^^^^^^^^^^^^^^^^^^^^^^^^^^^^^^^^^^^^^
  File "/home/sfullerton24/python/lib/python3.11/site-packages/psycopg2/__init__.py", line 122, in connect
    conn = _connect(dsn, connection_factory=connection_factory, **kwasync)
           ^^^^^^^^^^^^^^^^^^^^^^^^^^^^^^^^^^^^^^^^^^^^^^^^^^^^^^^^^^^^^^^
psycopg2.OperationalError: could not connect to server: Connection refused
	Is the server running on host "localhost" (127.0.0.1) and accepting
	TCP/IP connections on port 7449?


The above exception was the direct cause of the following exception:

Traceback (most recent call last):
  File "/home/sfullerton24/twitter_postgres_parallel/load_tweets_batch.py", line 416, in <module>
    connection = engine.connect()
                 ^^^^^^^^^^^^^^^^
  File "/home/sfullerton24/python/lib/python3.11/site-packages/sqlalchemy/engine/base.py", line 3279, in connect
    return self._connection_cls(self)
           ^^^^^^^^^^^^^^^^^^^^^^^^^^
  File "/home/sfullerton24/python/lib/python3.11/site-packages/sqlalchemy/engine/base.py", line 147, in __init__
    Connection._handle_dbapi_exception_noconnection(
  File "/home/sfullerton24/python/lib/python3.11/site-packages/sqlalchemy/engine/base.py", line 2443, in _handle_dbapi_exception_noconnection
    raise sqlalchemy_exception.with_traceback(exc_info[2]) from e
  File "/home/sfullerton24/python/lib/python3.11/site-packages/sqlalchemy/engine/base.py", line 145, in __init__
    self._dbapi_connection = engine.raw_connection()
                             ^^^^^^^^^^^^^^^^^^^^^^^
  File "/home/sfullerton24/python/lib/python3.11/site-packages/sqlalchemy/engine/base.py", line 3303, in raw_connection
    return self.pool.connect()
           ^^^^^^^^^^^^^^^^^^^
  File "/home/sfullerton24/python/lib/python3.11/site-packages/sqlalchemy/pool/base.py", line 449, in connect
    return _ConnectionFairy._checkout(self)
           ^^^^^^^^^^^^^^^^^^^^^^^^^^^^^^^^
  File "/home/sfullerton24/python/lib/python3.11/site-packages/sqlalchemy/pool/base.py", line 1263, in _checkout
    fairy = _ConnectionRecord.checkout(pool)
            ^^^^^^^^^^^^^^^^^^^^^^^^^^^^^^^^
  File "/home/sfullerton24/python/lib/python3.11/site-packages/sqlalchemy/pool/base.py", line 712, in checkout
    rec = pool._do_get()
          ^^^^^^^^^^^^^^
  File "/home/sfullerton24/python/lib/python3.11/site-packages/sqlalchemy/pool/impl.py", line 179, in _do_get
    with util.safe_reraise():
  File "/home/sfullerton24/python/lib/python3.11/site-packages/sqlalchemy/util/langhelpers.py", line 146, in __exit__
    raise exc_value.with_traceback(exc_tb)
  File "/home/sfullerton24/python/lib/python3.11/site-packages/sqlalchemy/pool/impl.py", line 177, in _do_get
    return self._create_connection()
           ^^^^^^^^^^^^^^^^^^^^^^^^^
  File "/home/sfullerton24/python/lib/python3.11/site-packages/sqlalchemy/pool/base.py", line 390, in _create_connection
    return _ConnectionRecord(self)
           ^^^^^^^^^^^^^^^^^^^^^^^
  File "/home/sfullerton24/python/lib/python3.11/site-packages/sqlalchemy/pool/base.py", line 674, in __init__
    self.__connect()
  File "/home/sfullerton24/python/lib/python3.11/site-packages/sqlalchemy/pool/base.py", line 900, in __connect
    with util.safe_reraise():
  File "/home/sfullerton24/python/lib/python3.11/site-packages/sqlalchemy/util/langhelpers.py", line 146, in __exit__
    raise exc_value.with_traceback(exc_tb)
  File "/home/sfullerton24/python/lib/python3.11/site-packages/sqlalchemy/pool/base.py", line 896, in __connect
    self.dbapi_connection = connection = pool._invoke_creator(self)
                                         ^^^^^^^^^^^^^^^^^^^^^^^^^^
  File "/home/sfullerton24/python/lib/python3.11/site-packages/sqlalchemy/engine/create.py", line 643, in connect
    return dialect.connect(*cargs, **cparams)
           ^^^^^^^^^^^^^^^^^^^^^^^^^^^^^^^^^^
  File "/home/sfullerton24/python/lib/python3.11/site-packages/sqlalchemy/engine/default.py", line 616, in connect
    return self.loaded_dbapi.connect(*cargs, **cparams)
           ^^^^^^^^^^^^^^^^^^^^^^^^^^^^^^^^^^^^^^^^^^^^
  File "/home/sfullerton24/python/lib/python3.11/site-packages/psycopg2/__init__.py", line 122, in connect
    conn = _connect(dsn, connection_factory=connection_factory, **kwasync)
           ^^^^^^^^^^^^^^^^^^^^^^^^^^^^^^^^^^^^^^^^^^^^^^^^^^^^^^^^^^^^^^^
sqlalchemy.exc.OperationalError: (psycopg2.OperationalError) could not connect to server: Connection refused
	Is the server running on host "localhost" (127.0.0.1) and accepting
	TCP/IP connections on port 7449?

(Background on this error at: https://sqlalche.me/e/20/e3q8)
Traceback (most recent call last):
  File "/home/sfullerton24/python/lib/python3.11/site-packages/sqlalchemy/engine/base.py", line 145, in __init__
    self._dbapi_connection = engine.raw_connection()
                             ^^^^^^^^^^^^^^^^^^^^^^^
  File "/home/sfullerton24/python/lib/python3.11/site-packages/sqlalchemy/engine/base.py", line 3303, in raw_connection
    return self.pool.connect()
           ^^^^^^^^^^^^^^^^^^^
  File "/home/sfullerton24/python/lib/python3.11/site-packages/sqlalchemy/pool/base.py", line 449, in connect
    return _ConnectionFairy._checkout(self)
           ^^^^^^^^^^^^^^^^^^^^^^^^^^^^^^^^
  File "/home/sfullerton24/python/lib/python3.11/site-packages/sqlalchemy/pool/base.py", line 1263, in _checkout
    fairy = _ConnectionRecord.checkout(pool)
            ^^^^^^^^^^^^^^^^^^^^^^^^^^^^^^^^
  File "/home/sfullerton24/python/lib/python3.11/site-packages/sqlalchemy/pool/base.py", line 712, in checkout
    rec = pool._do_get()
          ^^^^^^^^^^^^^^
  File "/home/sfullerton24/python/lib/python3.11/site-packages/sqlalchemy/pool/impl.py", line 179, in _do_get
    with util.safe_reraise():
  File "/home/sfullerton24/python/lib/python3.11/site-packages/sqlalchemy/util/langhelpers.py", line 146, in __exit__
    raise exc_value.with_traceback(exc_tb)
  File "/home/sfullerton24/python/lib/python3.11/site-packages/sqlalchemy/pool/impl.py", line 177, in _do_get
    return self._create_connection()
           ^^^^^^^^^^^^^^^^^^^^^^^^^
  File "/home/sfullerton24/python/lib/python3.11/site-packages/sqlalchemy/pool/base.py", line 390, in _create_connection
    return _ConnectionRecord(self)
           ^^^^^^^^^^^^^^^^^^^^^^^
  File "/home/sfullerton24/python/lib/python3.11/site-packages/sqlalchemy/pool/base.py", line 674, in __init__
    self.__connect()
  File "/home/sfullerton24/python/lib/python3.11/site-packages/sqlalchemy/pool/base.py", line 900, in __connect
    with util.safe_reraise():
  File "/home/sfullerton24/python/lib/python3.11/site-packages/sqlalchemy/util/langhelpers.py", line 146, in __exit__
    raise exc_value.with_traceback(exc_tb)
  File "/home/sfullerton24/python/lib/python3.11/site-packages/sqlalchemy/pool/base.py", line 896, in __connect
    self.dbapi_connection = connection = pool._invoke_creator(self)
                                         ^^^^^^^^^^^^^^^^^^^^^^^^^^
  File "/home/sfullerton24/python/lib/python3.11/site-packages/sqlalchemy/engine/create.py", line 643, in connect
    return dialect.connect(*cargs, **cparams)
           ^^^^^^^^^^^^^^^^^^^^^^^^^^^^^^^^^^
  File "/home/sfullerton24/python/lib/python3.11/site-packages/sqlalchemy/engine/default.py", line 616, in connect
    return self.loaded_dbapi.connect(*cargs, **cparams)
           ^^^^^^^^^^^^^^^^^^^^^^^^^^^^^^^^^^^^^^^^^^^^
  File "/home/sfullerton24/python/lib/python3.11/site-packages/psycopg2/__init__.py", line 122, in connect
    conn = _connect(dsn, connection_factory=connection_factory, **kwasync)
           ^^^^^^^^^^^^^^^^^^^^^^^^^^^^^^^^^^^^^^^^^^^^^^^^^^^^^^^^^^^^^^^
psycopg2.OperationalError: could not connect to server: Connection refused
	Is the server running on host "localhost" (127.0.0.1) and accepting
	TCP/IP connections on port 7449?


The above exception was the direct cause of the following exception:

Traceback (most recent call last):
  File "/home/sfullerton24/twitter_postgres_parallel/load_tweets_batch.py", line 416, in <module>
    connection = engine.connect()
                 ^^^^^^^^^^^^^^^^
  File "/home/sfullerton24/python/lib/python3.11/site-packages/sqlalchemy/engine/base.py", line 3279, in connect
    return self._connection_cls(self)
           ^^^^^^^^^^^^^^^^^^^^^^^^^^
  File "/home/sfullerton24/python/lib/python3.11/site-packages/sqlalchemy/engine/base.py", line 147, in __init__
    Connection._handle_dbapi_exception_noconnection(
  File "/home/sfullerton24/python/lib/python3.11/site-packages/sqlalchemy/engine/base.py", line 2443, in _handle_dbapi_exception_noconnection
    raise sqlalchemy_exception.with_traceback(exc_info[2]) from e
  File "/home/sfullerton24/python/lib/python3.11/site-packages/sqlalchemy/engine/base.py", line 145, in __init__
    self._dbapi_connection = engine.raw_connection()
                             ^^^^^^^^^^^^^^^^^^^^^^^
  File "/home/sfullerton24/python/lib/python3.11/site-packages/sqlalchemy/engine/base.py", line 3303, in raw_connection
    return self.pool.connect()
           ^^^^^^^^^^^^^^^^^^^
  File "/home/sfullerton24/python/lib/python3.11/site-packages/sqlalchemy/pool/base.py", line 449, in connect
    return _ConnectionFairy._checkout(self)
           ^^^^^^^^^^^^^^^^^^^^^^^^^^^^^^^^
  File "/home/sfullerton24/python/lib/python3.11/site-packages/sqlalchemy/pool/base.py", line 1263, in _checkout
    fairy = _ConnectionRecord.checkout(pool)
            ^^^^^^^^^^^^^^^^^^^^^^^^^^^^^^^^
  File "/home/sfullerton24/python/lib/python3.11/site-packages/sqlalchemy/pool/base.py", line 712, in checkout
    rec = pool._do_get()
          ^^^^^^^^^^^^^^
  File "/home/sfullerton24/python/lib/python3.11/site-packages/sqlalchemy/pool/impl.py", line 179, in _do_get
    with util.safe_reraise():
  File "/home/sfullerton24/python/lib/python3.11/site-packages/sqlalchemy/util/langhelpers.py", line 146, in __exit__
    raise exc_value.with_traceback(exc_tb)
  File "/home/sfullerton24/python/lib/python3.11/site-packages/sqlalchemy/pool/impl.py", line 177, in _do_get
    return self._create_connection()
           ^^^^^^^^^^^^^^^^^^^^^^^^^
  File "/home/sfullerton24/python/lib/python3.11/site-packages/sqlalchemy/pool/base.py", line 390, in _create_connection
    return _ConnectionRecord(self)
           ^^^^^^^^^^^^^^^^^^^^^^^
  File "/home/sfullerton24/python/lib/python3.11/site-packages/sqlalchemy/pool/base.py", line 674, in __init__
    self.__connect()
  File "/home/sfullerton24/python/lib/python3.11/site-packages/sqlalchemy/pool/base.py", line 900, in __connect
    with util.safe_reraise():
  File "/home/sfullerton24/python/lib/python3.11/site-packages/sqlalchemy/util/langhelpers.py", line 146, in __exit__
    raise exc_value.with_traceback(exc_tb)
  File "/home/sfullerton24/python/lib/python3.11/site-packages/sqlalchemy/pool/base.py", line 896, in __connect
    self.dbapi_connection = connection = pool._invoke_creator(self)
                                         ^^^^^^^^^^^^^^^^^^^^^^^^^^
  File "/home/sfullerton24/python/lib/python3.11/site-packages/sqlalchemy/engine/create.py", line 643, in connect
    return dialect.connect(*cargs, **cparams)
           ^^^^^^^^^^^^^^^^^^^^^^^^^^^^^^^^^^
  File "/home/sfullerton24/python/lib/python3.11/site-packages/sqlalchemy/engine/default.py", line 616, in connect
    return self.loaded_dbapi.connect(*cargs, **cparams)
           ^^^^^^^^^^^^^^^^^^^^^^^^^^^^^^^^^^^^^^^^^^^^
  File "/home/sfullerton24/python/lib/python3.11/site-packages/psycopg2/__init__.py", line 122, in connect
    conn = _connect(dsn, connection_factory=connection_factory, **kwasync)
           ^^^^^^^^^^^^^^^^^^^^^^^^^^^^^^^^^^^^^^^^^^^^^^^^^^^^^^^^^^^^^^^
sqlalchemy.exc.OperationalError: (psycopg2.OperationalError) could not connect to server: Connection refused
	Is the server running on host "localhost" (127.0.0.1) and accepting
	TCP/IP connections on port 7449?

(Background on this error at: https://sqlalche.me/e/20/e3q8)
Traceback (most recent call last):
  File "/home/sfullerton24/python/lib/python3.11/site-packages/sqlalchemy/engine/base.py", line 145, in __init__
    self._dbapi_connection = engine.raw_connection()
                             ^^^^^^^^^^^^^^^^^^^^^^^
  File "/home/sfullerton24/python/lib/python3.11/site-packages/sqlalchemy/engine/base.py", line 3303, in raw_connection
    return self.pool.connect()
           ^^^^^^^^^^^^^^^^^^^
  File "/home/sfullerton24/python/lib/python3.11/site-packages/sqlalchemy/pool/base.py", line 449, in connect
    return _ConnectionFairy._checkout(self)
           ^^^^^^^^^^^^^^^^^^^^^^^^^^^^^^^^
  File "/home/sfullerton24/python/lib/python3.11/site-packages/sqlalchemy/pool/base.py", line 1263, in _checkout
    fairy = _ConnectionRecord.checkout(pool)
            ^^^^^^^^^^^^^^^^^^^^^^^^^^^^^^^^
  File "/home/sfullerton24/python/lib/python3.11/site-packages/sqlalchemy/pool/base.py", line 712, in checkout
    rec = pool._do_get()
          ^^^^^^^^^^^^^^
  File "/home/sfullerton24/python/lib/python3.11/site-packages/sqlalchemy/pool/impl.py", line 179, in _do_get
    with util.safe_reraise():
  File "/home/sfullerton24/python/lib/python3.11/site-packages/sqlalchemy/util/langhelpers.py", line 146, in __exit__
    raise exc_value.with_traceback(exc_tb)
  File "/home/sfullerton24/python/lib/python3.11/site-packages/sqlalchemy/pool/impl.py", line 177, in _do_get
    return self._create_connection()
           ^^^^^^^^^^^^^^^^^^^^^^^^^
  File "/home/sfullerton24/python/lib/python3.11/site-packages/sqlalchemy/pool/base.py", line 390, in _create_connection
    return _ConnectionRecord(self)
           ^^^^^^^^^^^^^^^^^^^^^^^
  File "/home/sfullerton24/python/lib/python3.11/site-packages/sqlalchemy/pool/base.py", line 674, in __init__
    self.__connect()
  File "/home/sfullerton24/python/lib/python3.11/site-packages/sqlalchemy/pool/base.py", line 900, in __connect
    with util.safe_reraise():
  File "/home/sfullerton24/python/lib/python3.11/site-packages/sqlalchemy/util/langhelpers.py", line 146, in __exit__
    raise exc_value.with_traceback(exc_tb)
  File "/home/sfullerton24/python/lib/python3.11/site-packages/sqlalchemy/pool/base.py", line 896, in __connect
    self.dbapi_connection = connection = pool._invoke_creator(self)
                                         ^^^^^^^^^^^^^^^^^^^^^^^^^^
  File "/home/sfullerton24/python/lib/python3.11/site-packages/sqlalchemy/engine/create.py", line 643, in connect
    return dialect.connect(*cargs, **cparams)
           ^^^^^^^^^^^^^^^^^^^^^^^^^^^^^^^^^^
  File "/home/sfullerton24/python/lib/python3.11/site-packages/sqlalchemy/engine/default.py", line 616, in connect
    return self.loaded_dbapi.connect(*cargs, **cparams)
           ^^^^^^^^^^^^^^^^^^^^^^^^^^^^^^^^^^^^^^^^^^^^
  File "/home/sfullerton24/python/lib/python3.11/site-packages/psycopg2/__init__.py", line 122, in connect
    conn = _connect(dsn, connection_factory=connection_factory, **kwasync)
           ^^^^^^^^^^^^^^^^^^^^^^^^^^^^^^^^^^^^^^^^^^^^^^^^^^^^^^^^^^^^^^^
psycopg2.OperationalError: could not connect to server: Connection refused
	Is the server running on host "localhost" (127.0.0.1) and accepting
	TCP/IP connections on port 7449?


The above exception was the direct cause of the following exception:

Traceback (most recent call last):
  File "/home/sfullerton24/twitter_postgres_parallel/load_tweets_batch.py", line 416, in <module>
    connection = engine.connect()
                 ^^^^^^^^^^^^^^^^
  File "/home/sfullerton24/python/lib/python3.11/site-packages/sqlalchemy/engine/base.py", line 3279, in connect
    return self._connection_cls(self)
           ^^^^^^^^^^^^^^^^^^^^^^^^^^
  File "/home/sfullerton24/python/lib/python3.11/site-packages/sqlalchemy/engine/base.py", line 147, in __init__
    Connection._handle_dbapi_exception_noconnection(
  File "/home/sfullerton24/python/lib/python3.11/site-packages/sqlalchemy/engine/base.py", line 2443, in _handle_dbapi_exception_noconnection
    raise sqlalchemy_exception.with_traceback(exc_info[2]) from e
  File "/home/sfullerton24/python/lib/python3.11/site-packages/sqlalchemy/engine/base.py", line 145, in __init__
    self._dbapi_connection = engine.raw_connection()
                             ^^^^^^^^^^^^^^^^^^^^^^^
  File "/home/sfullerton24/python/lib/python3.11/site-packages/sqlalchemy/engine/base.py", line 3303, in raw_connection
    return self.pool.connect()
           ^^^^^^^^^^^^^^^^^^^
  File "/home/sfullerton24/python/lib/python3.11/site-packages/sqlalchemy/pool/base.py", line 449, in connect
    return _ConnectionFairy._checkout(self)
           ^^^^^^^^^^^^^^^^^^^^^^^^^^^^^^^^
  File "/home/sfullerton24/python/lib/python3.11/site-packages/sqlalchemy/pool/base.py", line 1263, in _checkout
    fairy = _ConnectionRecord.checkout(pool)
            ^^^^^^^^^^^^^^^^^^^^^^^^^^^^^^^^
  File "/home/sfullerton24/python/lib/python3.11/site-packages/sqlalchemy/pool/base.py", line 712, in checkout
    rec = pool._do_get()
          ^^^^^^^^^^^^^^
  File "/home/sfullerton24/python/lib/python3.11/site-packages/sqlalchemy/pool/impl.py", line 179, in _do_get
    with util.safe_reraise():
  File "/home/sfullerton24/python/lib/python3.11/site-packages/sqlalchemy/util/langhelpers.py", line 146, in __exit__
    raise exc_value.with_traceback(exc_tb)
  File "/home/sfullerton24/python/lib/python3.11/site-packages/sqlalchemy/pool/impl.py", line 177, in _do_get
    return self._create_connection()
           ^^^^^^^^^^^^^^^^^^^^^^^^^
  File "/home/sfullerton24/python/lib/python3.11/site-packages/sqlalchemy/pool/base.py", line 390, in _create_connection
    return _ConnectionRecord(self)
           ^^^^^^^^^^^^^^^^^^^^^^^
  File "/home/sfullerton24/python/lib/python3.11/site-packages/sqlalchemy/pool/base.py", line 674, in __init__
    self.__connect()
  File "/home/sfullerton24/python/lib/python3.11/site-packages/sqlalchemy/pool/base.py", line 900, in __connect
    with util.safe_reraise():
  File "/home/sfullerton24/python/lib/python3.11/site-packages/sqlalchemy/util/langhelpers.py", line 146, in __exit__
    raise exc_value.with_traceback(exc_tb)
  File "/home/sfullerton24/python/lib/python3.11/site-packages/sqlalchemy/pool/base.py", line 896, in __connect
    self.dbapi_connection = connection = pool._invoke_creator(self)
                                         ^^^^^^^^^^^^^^^^^^^^^^^^^^
  File "/home/sfullerton24/python/lib/python3.11/site-packages/sqlalchemy/engine/create.py", line 643, in connect
    return dialect.connect(*cargs, **cparams)
           ^^^^^^^^^^^^^^^^^^^^^^^^^^^^^^^^^^
  File "/home/sfullerton24/python/lib/python3.11/site-packages/sqlalchemy/engine/default.py", line 616, in connect
    return self.loaded_dbapi.connect(*cargs, **cparams)
           ^^^^^^^^^^^^^^^^^^^^^^^^^^^^^^^^^^^^^^^^^^^^
  File "/home/sfullerton24/python/lib/python3.11/site-packages/psycopg2/__init__.py", line 122, in connect
    conn = _connect(dsn, connection_factory=connection_factory, **kwasync)
           ^^^^^^^^^^^^^^^^^^^^^^^^^^^^^^^^^^^^^^^^^^^^^^^^^^^^^^^^^^^^^^^
sqlalchemy.exc.OperationalError: (psycopg2.OperationalError) could not connect to server: Connection refused
	Is the server running on host "localhost" (127.0.0.1) and accepting
	TCP/IP connections on port 7449?

(Background on this error at: https://sqlalche.me/e/20/e3q8)
Traceback (most recent call last):
  File "/home/sfullerton24/python/lib/python3.11/site-packages/sqlalchemy/engine/base.py", line 145, in __init__
    self._dbapi_connection = engine.raw_connection()
                             ^^^^^^^^^^^^^^^^^^^^^^^
  File "/home/sfullerton24/python/lib/python3.11/site-packages/sqlalchemy/engine/base.py", line 3303, in raw_connection
    return self.pool.connect()
           ^^^^^^^^^^^^^^^^^^^
  File "/home/sfullerton24/python/lib/python3.11/site-packages/sqlalchemy/pool/base.py", line 449, in connect
    return _ConnectionFairy._checkout(self)
           ^^^^^^^^^^^^^^^^^^^^^^^^^^^^^^^^
  File "/home/sfullerton24/python/lib/python3.11/site-packages/sqlalchemy/pool/base.py", line 1263, in _checkout
    fairy = _ConnectionRecord.checkout(pool)
            ^^^^^^^^^^^^^^^^^^^^^^^^^^^^^^^^
  File "/home/sfullerton24/python/lib/python3.11/site-packages/sqlalchemy/pool/base.py", line 712, in checkout
    rec = pool._do_get()
          ^^^^^^^^^^^^^^
  File "/home/sfullerton24/python/lib/python3.11/site-packages/sqlalchemy/pool/impl.py", line 179, in _do_get
    with util.safe_reraise():
  File "/home/sfullerton24/python/lib/python3.11/site-packages/sqlalchemy/util/langhelpers.py", line 146, in __exit__
    raise exc_value.with_traceback(exc_tb)
  File "/home/sfullerton24/python/lib/python3.11/site-packages/sqlalchemy/pool/impl.py", line 177, in _do_get
    return self._create_connection()
           ^^^^^^^^^^^^^^^^^^^^^^^^^
  File "/home/sfullerton24/python/lib/python3.11/site-packages/sqlalchemy/pool/base.py", line 390, in _create_connection
    return _ConnectionRecord(self)
           ^^^^^^^^^^^^^^^^^^^^^^^
  File "/home/sfullerton24/python/lib/python3.11/site-packages/sqlalchemy/pool/base.py", line 674, in __init__
    self.__connect()
  File "/home/sfullerton24/python/lib/python3.11/site-packages/sqlalchemy/pool/base.py", line 900, in __connect
    with util.safe_reraise():
  File "/home/sfullerton24/python/lib/python3.11/site-packages/sqlalchemy/util/langhelpers.py", line 146, in __exit__
    raise exc_value.with_traceback(exc_tb)
  File "/home/sfullerton24/python/lib/python3.11/site-packages/sqlalchemy/pool/base.py", line 896, in __connect
    self.dbapi_connection = connection = pool._invoke_creator(self)
                                         ^^^^^^^^^^^^^^^^^^^^^^^^^^
  File "/home/sfullerton24/python/lib/python3.11/site-packages/sqlalchemy/engine/create.py", line 643, in connect
    return dialect.connect(*cargs, **cparams)
           ^^^^^^^^^^^^^^^^^^^^^^^^^^^^^^^^^^
  File "/home/sfullerton24/python/lib/python3.11/site-packages/sqlalchemy/engine/default.py", line 616, in connect
    return self.loaded_dbapi.connect(*cargs, **cparams)
           ^^^^^^^^^^^^^^^^^^^^^^^^^^^^^^^^^^^^^^^^^^^^
  File "/home/sfullerton24/python/lib/python3.11/site-packages/psycopg2/__init__.py", line 122, in connect
    conn = _connect(dsn, connection_factory=connection_factory, **kwasync)
           ^^^^^^^^^^^^^^^^^^^^^^^^^^^^^^^^^^^^^^^^^^^^^^^^^^^^^^^^^^^^^^^
psycopg2.OperationalError: could not connect to server: Connection refused
	Is the server running on host "localhost" (127.0.0.1) and accepting
	TCP/IP connections on port 7449?


The above exception was the direct cause of the following exception:

Traceback (most recent call last):
  File "/home/sfullerton24/twitter_postgres_parallel/load_tweets_batch.py", line 416, in <module>
    connection = engine.connect()
                 ^^^^^^^^^^^^^^^^
  File "/home/sfullerton24/python/lib/python3.11/site-packages/sqlalchemy/engine/base.py", line 3279, in connect
    return self._connection_cls(self)
           ^^^^^^^^^^^^^^^^^^^^^^^^^^
  File "/home/sfullerton24/python/lib/python3.11/site-packages/sqlalchemy/engine/base.py", line 147, in __init__
    Connection._handle_dbapi_exception_noconnection(
  File "/home/sfullerton24/python/lib/python3.11/site-packages/sqlalchemy/engine/base.py", line 2443, in _handle_dbapi_exception_noconnection
    raise sqlalchemy_exception.with_traceback(exc_info[2]) from e
  File "/home/sfullerton24/python/lib/python3.11/site-packages/sqlalchemy/engine/base.py", line 145, in __init__
    self._dbapi_connection = engine.raw_connection()
                             ^^^^^^^^^^^^^^^^^^^^^^^
  File "/home/sfullerton24/python/lib/python3.11/site-packages/sqlalchemy/engine/base.py", line 3303, in raw_connection
    return self.pool.connect()
           ^^^^^^^^^^^^^^^^^^^
  File "/home/sfullerton24/python/lib/python3.11/site-packages/sqlalchemy/pool/base.py", line 449, in connect
    return _ConnectionFairy._checkout(self)
           ^^^^^^^^^^^^^^^^^^^^^^^^^^^^^^^^
  File "/home/sfullerton24/python/lib/python3.11/site-packages/sqlalchemy/pool/base.py", line 1263, in _checkout
    fairy = _ConnectionRecord.checkout(pool)
            ^^^^^^^^^^^^^^^^^^^^^^^^^^^^^^^^
  File "/home/sfullerton24/python/lib/python3.11/site-packages/sqlalchemy/pool/base.py", line 712, in checkout
    rec = pool._do_get()
          ^^^^^^^^^^^^^^
  File "/home/sfullerton24/python/lib/python3.11/site-packages/sqlalchemy/pool/impl.py", line 179, in _do_get
    with util.safe_reraise():
  File "/home/sfullerton24/python/lib/python3.11/site-packages/sqlalchemy/util/langhelpers.py", line 146, in __exit__
    raise exc_value.with_traceback(exc_tb)
  File "/home/sfullerton24/python/lib/python3.11/site-packages/sqlalchemy/pool/impl.py", line 177, in _do_get
    return self._create_connection()
           ^^^^^^^^^^^^^^^^^^^^^^^^^
  File "/home/sfullerton24/python/lib/python3.11/site-packages/sqlalchemy/pool/base.py", line 390, in _create_connection
    return _ConnectionRecord(self)
           ^^^^^^^^^^^^^^^^^^^^^^^
  File "/home/sfullerton24/python/lib/python3.11/site-packages/sqlalchemy/pool/base.py", line 674, in __init__
    self.__connect()
  File "/home/sfullerton24/python/lib/python3.11/site-packages/sqlalchemy/pool/base.py", line 900, in __connect
    with util.safe_reraise():
  File "/home/sfullerton24/python/lib/python3.11/site-packages/sqlalchemy/util/langhelpers.py", line 146, in __exit__
    raise exc_value.with_traceback(exc_tb)
  File "/home/sfullerton24/python/lib/python3.11/site-packages/sqlalchemy/pool/base.py", line 896, in __connect
    self.dbapi_connection = connection = pool._invoke_creator(self)
                                         ^^^^^^^^^^^^^^^^^^^^^^^^^^
  File "/home/sfullerton24/python/lib/python3.11/site-packages/sqlalchemy/engine/create.py", line 643, in connect
    return dialect.connect(*cargs, **cparams)
           ^^^^^^^^^^^^^^^^^^^^^^^^^^^^^^^^^^
  File "/home/sfullerton24/python/lib/python3.11/site-packages/sqlalchemy/engine/default.py", line 616, in connect
    return self.loaded_dbapi.connect(*cargs, **cparams)
           ^^^^^^^^^^^^^^^^^^^^^^^^^^^^^^^^^^^^^^^^^^^^
  File "/home/sfullerton24/python/lib/python3.11/site-packages/psycopg2/__init__.py", line 122, in connect
    conn = _connect(dsn, connection_factory=connection_factory, **kwasync)
           ^^^^^^^^^^^^^^^^^^^^^^^^^^^^^^^^^^^^^^^^^^^^^^^^^^^^^^^^^^^^^^^
sqlalchemy.exc.OperationalError: (psycopg2.OperationalError) could not connect to server: Connection refused
	Is the server running on host "localhost" (127.0.0.1) and accepting
	TCP/IP connections on port 7449?

(Background on this error at: https://sqlalche.me/e/20/e3q8)
Traceback (most recent call last):
  File "/home/sfullerton24/python/lib/python3.11/site-packages/sqlalchemy/engine/base.py", line 145, in __init__
    self._dbapi_connection = engine.raw_connection()
                             ^^^^^^^^^^^^^^^^^^^^^^^
  File "/home/sfullerton24/python/lib/python3.11/site-packages/sqlalchemy/engine/base.py", line 3303, in raw_connection
    return self.pool.connect()
           ^^^^^^^^^^^^^^^^^^^
  File "/home/sfullerton24/python/lib/python3.11/site-packages/sqlalchemy/pool/base.py", line 449, in connect
    return _ConnectionFairy._checkout(self)
           ^^^^^^^^^^^^^^^^^^^^^^^^^^^^^^^^
  File "/home/sfullerton24/python/lib/python3.11/site-packages/sqlalchemy/pool/base.py", line 1263, in _checkout
    fairy = _ConnectionRecord.checkout(pool)
            ^^^^^^^^^^^^^^^^^^^^^^^^^^^^^^^^
  File "/home/sfullerton24/python/lib/python3.11/site-packages/sqlalchemy/pool/base.py", line 712, in checkout
    rec = pool._do_get()
          ^^^^^^^^^^^^^^
  File "/home/sfullerton24/python/lib/python3.11/site-packages/sqlalchemy/pool/impl.py", line 179, in _do_get
    with util.safe_reraise():
  File "/home/sfullerton24/python/lib/python3.11/site-packages/sqlalchemy/util/langhelpers.py", line 146, in __exit__
    raise exc_value.with_traceback(exc_tb)
  File "/home/sfullerton24/python/lib/python3.11/site-packages/sqlalchemy/pool/impl.py", line 177, in _do_get
    return self._create_connection()
           ^^^^^^^^^^^^^^^^^^^^^^^^^
  File "/home/sfullerton24/python/lib/python3.11/site-packages/sqlalchemy/pool/base.py", line 390, in _create_connection
    return _ConnectionRecord(self)
           ^^^^^^^^^^^^^^^^^^^^^^^
  File "/home/sfullerton24/python/lib/python3.11/site-packages/sqlalchemy/pool/base.py", line 674, in __init__
    self.__connect()
  File "/home/sfullerton24/python/lib/python3.11/site-packages/sqlalchemy/pool/base.py", line 900, in __connect
    with util.safe_reraise():
  File "/home/sfullerton24/python/lib/python3.11/site-packages/sqlalchemy/util/langhelpers.py", line 146, in __exit__
    raise exc_value.with_traceback(exc_tb)
  File "/home/sfullerton24/python/lib/python3.11/site-packages/sqlalchemy/pool/base.py", line 896, in __connect
    self.dbapi_connection = connection = pool._invoke_creator(self)
                                         ^^^^^^^^^^^^^^^^^^^^^^^^^^
  File "/home/sfullerton24/python/lib/python3.11/site-packages/sqlalchemy/engine/create.py", line 643, in connect
    return dialect.connect(*cargs, **cparams)
           ^^^^^^^^^^^^^^^^^^^^^^^^^^^^^^^^^^
  File "/home/sfullerton24/python/lib/python3.11/site-packages/sqlalchemy/engine/default.py", line 616, in connect
    return self.loaded_dbapi.connect(*cargs, **cparams)
           ^^^^^^^^^^^^^^^^^^^^^^^^^^^^^^^^^^^^^^^^^^^^
  File "/home/sfullerton24/python/lib/python3.11/site-packages/psycopg2/__init__.py", line 122, in connect
    conn = _connect(dsn, connection_factory=connection_factory, **kwasync)
           ^^^^^^^^^^^^^^^^^^^^^^^^^^^^^^^^^^^^^^^^^^^^^^^^^^^^^^^^^^^^^^^
psycopg2.OperationalError: could not connect to server: Connection refused
	Is the server running on host "localhost" (127.0.0.1) and accepting
	TCP/IP connections on port 7449?


The above exception was the direct cause of the following exception:

Traceback (most recent call last):
  File "/home/sfullerton24/twitter_postgres_parallel/load_tweets_batch.py", line 416, in <module>
    connection = engine.connect()
                 ^^^^^^^^^^^^^^^^
  File "/home/sfullerton24/python/lib/python3.11/site-packages/sqlalchemy/engine/base.py", line 3279, in connect
    return self._connection_cls(self)
           ^^^^^^^^^^^^^^^^^^^^^^^^^^
  File "/home/sfullerton24/python/lib/python3.11/site-packages/sqlalchemy/engine/base.py", line 147, in __init__
    Connection._handle_dbapi_exception_noconnection(
  File "/home/sfullerton24/python/lib/python3.11/site-packages/sqlalchemy/engine/base.py", line 2443, in _handle_dbapi_exception_noconnection
    raise sqlalchemy_exception.with_traceback(exc_info[2]) from e
  File "/home/sfullerton24/python/lib/python3.11/site-packages/sqlalchemy/engine/base.py", line 145, in __init__
    self._dbapi_connection = engine.raw_connection()
                             ^^^^^^^^^^^^^^^^^^^^^^^
  File "/home/sfullerton24/python/lib/python3.11/site-packages/sqlalchemy/engine/base.py", line 3303, in raw_connection
    return self.pool.connect()
           ^^^^^^^^^^^^^^^^^^^
  File "/home/sfullerton24/python/lib/python3.11/site-packages/sqlalchemy/pool/base.py", line 449, in connect
    return _ConnectionFairy._checkout(self)
           ^^^^^^^^^^^^^^^^^^^^^^^^^^^^^^^^
  File "/home/sfullerton24/python/lib/python3.11/site-packages/sqlalchemy/pool/base.py", line 1263, in _checkout
    fairy = _ConnectionRecord.checkout(pool)
            ^^^^^^^^^^^^^^^^^^^^^^^^^^^^^^^^
  File "/home/sfullerton24/python/lib/python3.11/site-packages/sqlalchemy/pool/base.py", line 712, in checkout
    rec = pool._do_get()
          ^^^^^^^^^^^^^^
  File "/home/sfullerton24/python/lib/python3.11/site-packages/sqlalchemy/pool/impl.py", line 179, in _do_get
    with util.safe_reraise():
  File "/home/sfullerton24/python/lib/python3.11/site-packages/sqlalchemy/util/langhelpers.py", line 146, in __exit__
    raise exc_value.with_traceback(exc_tb)
  File "/home/sfullerton24/python/lib/python3.11/site-packages/sqlalchemy/pool/impl.py", line 177, in _do_get
    return self._create_connection()
           ^^^^^^^^^^^^^^^^^^^^^^^^^
  File "/home/sfullerton24/python/lib/python3.11/site-packages/sqlalchemy/pool/base.py", line 390, in _create_connection
    return _ConnectionRecord(self)
           ^^^^^^^^^^^^^^^^^^^^^^^
  File "/home/sfullerton24/python/lib/python3.11/site-packages/sqlalchemy/pool/base.py", line 674, in __init__
    self.__connect()
  File "/home/sfullerton24/python/lib/python3.11/site-packages/sqlalchemy/pool/base.py", line 900, in __connect
    with util.safe_reraise():
  File "/home/sfullerton24/python/lib/python3.11/site-packages/sqlalchemy/util/langhelpers.py", line 146, in __exit__
    raise exc_value.with_traceback(exc_tb)
  File "/home/sfullerton24/python/lib/python3.11/site-packages/sqlalchemy/pool/base.py", line 896, in __connect
    self.dbapi_connection = connection = pool._invoke_creator(self)
                                         ^^^^^^^^^^^^^^^^^^^^^^^^^^
  File "/home/sfullerton24/python/lib/python3.11/site-packages/sqlalchemy/engine/create.py", line 643, in connect
    return dialect.connect(*cargs, **cparams)
           ^^^^^^^^^^^^^^^^^^^^^^^^^^^^^^^^^^
  File "/home/sfullerton24/python/lib/python3.11/site-packages/sqlalchemy/engine/default.py", line 616, in connect
    return self.loaded_dbapi.connect(*cargs, **cparams)
           ^^^^^^^^^^^^^^^^^^^^^^^^^^^^^^^^^^^^^^^^^^^^
  File "/home/sfullerton24/python/lib/python3.11/site-packages/psycopg2/__init__.py", line 122, in connect
    conn = _connect(dsn, connection_factory=connection_factory, **kwasync)
           ^^^^^^^^^^^^^^^^^^^^^^^^^^^^^^^^^^^^^^^^^^^^^^^^^^^^^^^^^^^^^^^
sqlalchemy.exc.OperationalError: (psycopg2.OperationalError) could not connect to server: Connection refused
	Is the server running on host "localhost" (127.0.0.1) and accepting
	TCP/IP connections on port 7449?

(Background on this error at: https://sqlalche.me/e/20/e3q8)
Traceback (most recent call last):
  File "/home/sfullerton24/python/lib/python3.11/site-packages/sqlalchemy/engine/base.py", line 145, in __init__
    self._dbapi_connection = engine.raw_connection()
                             ^^^^^^^^^^^^^^^^^^^^^^^
  File "/home/sfullerton24/python/lib/python3.11/site-packages/sqlalchemy/engine/base.py", line 3303, in raw_connection
    return self.pool.connect()
           ^^^^^^^^^^^^^^^^^^^
  File "/home/sfullerton24/python/lib/python3.11/site-packages/sqlalchemy/pool/base.py", line 449, in connect
    return _ConnectionFairy._checkout(self)
           ^^^^^^^^^^^^^^^^^^^^^^^^^^^^^^^^
  File "/home/sfullerton24/python/lib/python3.11/site-packages/sqlalchemy/pool/base.py", line 1263, in _checkout
    fairy = _ConnectionRecord.checkout(pool)
            ^^^^^^^^^^^^^^^^^^^^^^^^^^^^^^^^
  File "/home/sfullerton24/python/lib/python3.11/site-packages/sqlalchemy/pool/base.py", line 712, in checkout
    rec = pool._do_get()
          ^^^^^^^^^^^^^^
  File "/home/sfullerton24/python/lib/python3.11/site-packages/sqlalchemy/pool/impl.py", line 179, in _do_get
    with util.safe_reraise():
  File "/home/sfullerton24/python/lib/python3.11/site-packages/sqlalchemy/util/langhelpers.py", line 146, in __exit__
    raise exc_value.with_traceback(exc_tb)
  File "/home/sfullerton24/python/lib/python3.11/site-packages/sqlalchemy/pool/impl.py", line 177, in _do_get
    return self._create_connection()
           ^^^^^^^^^^^^^^^^^^^^^^^^^
  File "/home/sfullerton24/python/lib/python3.11/site-packages/sqlalchemy/pool/base.py", line 390, in _create_connection
    return _ConnectionRecord(self)
           ^^^^^^^^^^^^^^^^^^^^^^^
  File "/home/sfullerton24/python/lib/python3.11/site-packages/sqlalchemy/pool/base.py", line 674, in __init__
    self.__connect()
  File "/home/sfullerton24/python/lib/python3.11/site-packages/sqlalchemy/pool/base.py", line 900, in __connect
    with util.safe_reraise():
  File "/home/sfullerton24/python/lib/python3.11/site-packages/sqlalchemy/util/langhelpers.py", line 146, in __exit__
    raise exc_value.with_traceback(exc_tb)
  File "/home/sfullerton24/python/lib/python3.11/site-packages/sqlalchemy/pool/base.py", line 896, in __connect
    self.dbapi_connection = connection = pool._invoke_creator(self)
                                         ^^^^^^^^^^^^^^^^^^^^^^^^^^
  File "/home/sfullerton24/python/lib/python3.11/site-packages/sqlalchemy/engine/create.py", line 643, in connect
    return dialect.connect(*cargs, **cparams)
           ^^^^^^^^^^^^^^^^^^^^^^^^^^^^^^^^^^
  File "/home/sfullerton24/python/lib/python3.11/site-packages/sqlalchemy/engine/default.py", line 616, in connect
    return self.loaded_dbapi.connect(*cargs, **cparams)
           ^^^^^^^^^^^^^^^^^^^^^^^^^^^^^^^^^^^^^^^^^^^^
  File "/home/sfullerton24/python/lib/python3.11/site-packages/psycopg2/__init__.py", line 122, in connect
    conn = _connect(dsn, connection_factory=connection_factory, **kwasync)
           ^^^^^^^^^^^^^^^^^^^^^^^^^^^^^^^^^^^^^^^^^^^^^^^^^^^^^^^^^^^^^^^
psycopg2.OperationalError: could not connect to server: Connection refused
	Is the server running on host "localhost" (127.0.0.1) and accepting
	TCP/IP connections on port 7449?


The above exception was the direct cause of the following exception:

Traceback (most recent call last):
  File "/home/sfullerton24/twitter_postgres_parallel/load_tweets_batch.py", line 416, in <module>
    connection = engine.connect()
                 ^^^^^^^^^^^^^^^^
  File "/home/sfullerton24/python/lib/python3.11/site-packages/sqlalchemy/engine/base.py", line 3279, in connect
    return self._connection_cls(self)
           ^^^^^^^^^^^^^^^^^^^^^^^^^^
  File "/home/sfullerton24/python/lib/python3.11/site-packages/sqlalchemy/engine/base.py", line 147, in __init__
    Connection._handle_dbapi_exception_noconnection(
  File "/home/sfullerton24/python/lib/python3.11/site-packages/sqlalchemy/engine/base.py", line 2443, in _handle_dbapi_exception_noconnection
    raise sqlalchemy_exception.with_traceback(exc_info[2]) from e
  File "/home/sfullerton24/python/lib/python3.11/site-packages/sqlalchemy/engine/base.py", line 145, in __init__
    self._dbapi_connection = engine.raw_connection()
                             ^^^^^^^^^^^^^^^^^^^^^^^
  File "/home/sfullerton24/python/lib/python3.11/site-packages/sqlalchemy/engine/base.py", line 3303, in raw_connection
    return self.pool.connect()
           ^^^^^^^^^^^^^^^^^^^
  File "/home/sfullerton24/python/lib/python3.11/site-packages/sqlalchemy/pool/base.py", line 449, in connect
    return _ConnectionFairy._checkout(self)
           ^^^^^^^^^^^^^^^^^^^^^^^^^^^^^^^^
  File "/home/sfullerton24/python/lib/python3.11/site-packages/sqlalchemy/pool/base.py", line 1263, in _checkout
    fairy = _ConnectionRecord.checkout(pool)
            ^^^^^^^^^^^^^^^^^^^^^^^^^^^^^^^^
  File "/home/sfullerton24/python/lib/python3.11/site-packages/sqlalchemy/pool/base.py", line 712, in checkout
    rec = pool._do_get()
          ^^^^^^^^^^^^^^
  File "/home/sfullerton24/python/lib/python3.11/site-packages/sqlalchemy/pool/impl.py", line 179, in _do_get
    with util.safe_reraise():
  File "/home/sfullerton24/python/lib/python3.11/site-packages/sqlalchemy/util/langhelpers.py", line 146, in __exit__
    raise exc_value.with_traceback(exc_tb)
  File "/home/sfullerton24/python/lib/python3.11/site-packages/sqlalchemy/pool/impl.py", line 177, in _do_get
    return self._create_connection()
           ^^^^^^^^^^^^^^^^^^^^^^^^^
  File "/home/sfullerton24/python/lib/python3.11/site-packages/sqlalchemy/pool/base.py", line 390, in _create_connection
    return _ConnectionRecord(self)
           ^^^^^^^^^^^^^^^^^^^^^^^
  File "/home/sfullerton24/python/lib/python3.11/site-packages/sqlalchemy/pool/base.py", line 674, in __init__
    self.__connect()
  File "/home/sfullerton24/python/lib/python3.11/site-packages/sqlalchemy/pool/base.py", line 900, in __connect
    with util.safe_reraise():
  File "/home/sfullerton24/python/lib/python3.11/site-packages/sqlalchemy/util/langhelpers.py", line 146, in __exit__
    raise exc_value.with_traceback(exc_tb)
  File "/home/sfullerton24/python/lib/python3.11/site-packages/sqlalchemy/pool/base.py", line 896, in __connect
    self.dbapi_connection = connection = pool._invoke_creator(self)
                                         ^^^^^^^^^^^^^^^^^^^^^^^^^^
  File "/home/sfullerton24/python/lib/python3.11/site-packages/sqlalchemy/engine/create.py", line 643, in connect
    return dialect.connect(*cargs, **cparams)
           ^^^^^^^^^^^^^^^^^^^^^^^^^^^^^^^^^^
  File "/home/sfullerton24/python/lib/python3.11/site-packages/sqlalchemy/engine/default.py", line 616, in connect
    return self.loaded_dbapi.connect(*cargs, **cparams)
           ^^^^^^^^^^^^^^^^^^^^^^^^^^^^^^^^^^^^^^^^^^^^
  File "/home/sfullerton24/python/lib/python3.11/site-packages/psycopg2/__init__.py", line 122, in connect
    conn = _connect(dsn, connection_factory=connection_factory, **kwasync)
           ^^^^^^^^^^^^^^^^^^^^^^^^^^^^^^^^^^^^^^^^^^^^^^^^^^^^^^^^^^^^^^^
sqlalchemy.exc.OperationalError: (psycopg2.OperationalError) could not connect to server: Connection refused
	Is the server running on host "localhost" (127.0.0.1) and accepting
	TCP/IP connections on port 7449?

(Background on this error at: https://sqlalche.me/e/20/e3q8)
Traceback (most recent call last):
  File "/home/sfullerton24/python/lib/python3.11/site-packages/sqlalchemy/engine/base.py", line 145, in __init__
    self._dbapi_connection = engine.raw_connection()
                             ^^^^^^^^^^^^^^^^^^^^^^^
  File "/home/sfullerton24/python/lib/python3.11/site-packages/sqlalchemy/engine/base.py", line 3303, in raw_connection
    return self.pool.connect()
           ^^^^^^^^^^^^^^^^^^^
  File "/home/sfullerton24/python/lib/python3.11/site-packages/sqlalchemy/pool/base.py", line 449, in connect
    return _ConnectionFairy._checkout(self)
           ^^^^^^^^^^^^^^^^^^^^^^^^^^^^^^^^
  File "/home/sfullerton24/python/lib/python3.11/site-packages/sqlalchemy/pool/base.py", line 1263, in _checkout
    fairy = _ConnectionRecord.checkout(pool)
            ^^^^^^^^^^^^^^^^^^^^^^^^^^^^^^^^
  File "/home/sfullerton24/python/lib/python3.11/site-packages/sqlalchemy/pool/base.py", line 712, in checkout
    rec = pool._do_get()
          ^^^^^^^^^^^^^^
  File "/home/sfullerton24/python/lib/python3.11/site-packages/sqlalchemy/pool/impl.py", line 179, in _do_get
    with util.safe_reraise():
  File "/home/sfullerton24/python/lib/python3.11/site-packages/sqlalchemy/util/langhelpers.py", line 146, in __exit__
    raise exc_value.with_traceback(exc_tb)
  File "/home/sfullerton24/python/lib/python3.11/site-packages/sqlalchemy/pool/impl.py", line 177, in _do_get
    return self._create_connection()
           ^^^^^^^^^^^^^^^^^^^^^^^^^
  File "/home/sfullerton24/python/lib/python3.11/site-packages/sqlalchemy/pool/base.py", line 390, in _create_connection
    return _ConnectionRecord(self)
           ^^^^^^^^^^^^^^^^^^^^^^^
  File "/home/sfullerton24/python/lib/python3.11/site-packages/sqlalchemy/pool/base.py", line 674, in __init__
    self.__connect()
  File "/home/sfullerton24/python/lib/python3.11/site-packages/sqlalchemy/pool/base.py", line 900, in __connect
    with util.safe_reraise():
  File "/home/sfullerton24/python/lib/python3.11/site-packages/sqlalchemy/util/langhelpers.py", line 146, in __exit__
    raise exc_value.with_traceback(exc_tb)
  File "/home/sfullerton24/python/lib/python3.11/site-packages/sqlalchemy/pool/base.py", line 896, in __connect
    self.dbapi_connection = connection = pool._invoke_creator(self)
                                         ^^^^^^^^^^^^^^^^^^^^^^^^^^
  File "/home/sfullerton24/python/lib/python3.11/site-packages/sqlalchemy/engine/create.py", line 643, in connect
    return dialect.connect(*cargs, **cparams)
           ^^^^^^^^^^^^^^^^^^^^^^^^^^^^^^^^^^
  File "/home/sfullerton24/python/lib/python3.11/site-packages/sqlalchemy/engine/default.py", line 616, in connect
    return self.loaded_dbapi.connect(*cargs, **cparams)
           ^^^^^^^^^^^^^^^^^^^^^^^^^^^^^^^^^^^^^^^^^^^^
  File "/home/sfullerton24/python/lib/python3.11/site-packages/psycopg2/__init__.py", line 122, in connect
    conn = _connect(dsn, connection_factory=connection_factory, **kwasync)
           ^^^^^^^^^^^^^^^^^^^^^^^^^^^^^^^^^^^^^^^^^^^^^^^^^^^^^^^^^^^^^^^
psycopg2.OperationalError: could not connect to server: Connection refused
	Is the server running on host "localhost" (127.0.0.1) and accepting
	TCP/IP connections on port 7449?


The above exception was the direct cause of the following exception:

Traceback (most recent call last):
  File "/home/sfullerton24/twitter_postgres_parallel/load_tweets_batch.py", line 416, in <module>
    connection = engine.connect()
                 ^^^^^^^^^^^^^^^^
  File "/home/sfullerton24/python/lib/python3.11/site-packages/sqlalchemy/engine/base.py", line 3279, in connect
    return self._connection_cls(self)
           ^^^^^^^^^^^^^^^^^^^^^^^^^^
  File "/home/sfullerton24/python/lib/python3.11/site-packages/sqlalchemy/engine/base.py", line 147, in __init__
    Connection._handle_dbapi_exception_noconnection(
  File "/home/sfullerton24/python/lib/python3.11/site-packages/sqlalchemy/engine/base.py", line 2443, in _handle_dbapi_exception_noconnection
    raise sqlalchemy_exception.with_traceback(exc_info[2]) from e
  File "/home/sfullerton24/python/lib/python3.11/site-packages/sqlalchemy/engine/base.py", line 145, in __init__
    self._dbapi_connection = engine.raw_connection()
                             ^^^^^^^^^^^^^^^^^^^^^^^
  File "/home/sfullerton24/python/lib/python3.11/site-packages/sqlalchemy/engine/base.py", line 3303, in raw_connection
    return self.pool.connect()
           ^^^^^^^^^^^^^^^^^^^
  File "/home/sfullerton24/python/lib/python3.11/site-packages/sqlalchemy/pool/base.py", line 449, in connect
    return _ConnectionFairy._checkout(self)
           ^^^^^^^^^^^^^^^^^^^^^^^^^^^^^^^^
  File "/home/sfullerton24/python/lib/python3.11/site-packages/sqlalchemy/pool/base.py", line 1263, in _checkout
    fairy = _ConnectionRecord.checkout(pool)
            ^^^^^^^^^^^^^^^^^^^^^^^^^^^^^^^^
  File "/home/sfullerton24/python/lib/python3.11/site-packages/sqlalchemy/pool/base.py", line 712, in checkout
    rec = pool._do_get()
          ^^^^^^^^^^^^^^
  File "/home/sfullerton24/python/lib/python3.11/site-packages/sqlalchemy/pool/impl.py", line 179, in _do_get
    with util.safe_reraise():
  File "/home/sfullerton24/python/lib/python3.11/site-packages/sqlalchemy/util/langhelpers.py", line 146, in __exit__
    raise exc_value.with_traceback(exc_tb)
  File "/home/sfullerton24/python/lib/python3.11/site-packages/sqlalchemy/pool/impl.py", line 177, in _do_get
    return self._create_connection()
           ^^^^^^^^^^^^^^^^^^^^^^^^^
  File "/home/sfullerton24/python/lib/python3.11/site-packages/sqlalchemy/pool/base.py", line 390, in _create_connection
    return _ConnectionRecord(self)
           ^^^^^^^^^^^^^^^^^^^^^^^
  File "/home/sfullerton24/python/lib/python3.11/site-packages/sqlalchemy/pool/base.py", line 674, in __init__
    self.__connect()
  File "/home/sfullerton24/python/lib/python3.11/site-packages/sqlalchemy/pool/base.py", line 900, in __connect
    with util.safe_reraise():
  File "/home/sfullerton24/python/lib/python3.11/site-packages/sqlalchemy/util/langhelpers.py", line 146, in __exit__
    raise exc_value.with_traceback(exc_tb)
  File "/home/sfullerton24/python/lib/python3.11/site-packages/sqlalchemy/pool/base.py", line 896, in __connect
    self.dbapi_connection = connection = pool._invoke_creator(self)
                                         ^^^^^^^^^^^^^^^^^^^^^^^^^^
  File "/home/sfullerton24/python/lib/python3.11/site-packages/sqlalchemy/engine/create.py", line 643, in connect
    return dialect.connect(*cargs, **cparams)
           ^^^^^^^^^^^^^^^^^^^^^^^^^^^^^^^^^^
  File "/home/sfullerton24/python/lib/python3.11/site-packages/sqlalchemy/engine/default.py", line 616, in connect
    return self.loaded_dbapi.connect(*cargs, **cparams)
           ^^^^^^^^^^^^^^^^^^^^^^^^^^^^^^^^^^^^^^^^^^^^
  File "/home/sfullerton24/python/lib/python3.11/site-packages/psycopg2/__init__.py", line 122, in connect
    conn = _connect(dsn, connection_factory=connection_factory, **kwasync)
           ^^^^^^^^^^^^^^^^^^^^^^^^^^^^^^^^^^^^^^^^^^^^^^^^^^^^^^^^^^^^^^^
sqlalchemy.exc.OperationalError: (psycopg2.OperationalError) could not connect to server: Connection refused
	Is the server running on host "localhost" (127.0.0.1) and accepting
	TCP/IP connections on port 7449?

(Background on this error at: https://sqlalche.me/e/20/e3q8)
Traceback (most recent call last):
  File "/home/sfullerton24/python/lib/python3.11/site-packages/sqlalchemy/engine/base.py", line 145, in __init__
    self._dbapi_connection = engine.raw_connection()
                             ^^^^^^^^^^^^^^^^^^^^^^^
  File "/home/sfullerton24/python/lib/python3.11/site-packages/sqlalchemy/engine/base.py", line 3303, in raw_connection
    return self.pool.connect()
           ^^^^^^^^^^^^^^^^^^^
  File "/home/sfullerton24/python/lib/python3.11/site-packages/sqlalchemy/pool/base.py", line 449, in connect
    return _ConnectionFairy._checkout(self)
           ^^^^^^^^^^^^^^^^^^^^^^^^^^^^^^^^
  File "/home/sfullerton24/python/lib/python3.11/site-packages/sqlalchemy/pool/base.py", line 1263, in _checkout
    fairy = _ConnectionRecord.checkout(pool)
            ^^^^^^^^^^^^^^^^^^^^^^^^^^^^^^^^
  File "/home/sfullerton24/python/lib/python3.11/site-packages/sqlalchemy/pool/base.py", line 712, in checkout
    rec = pool._do_get()
          ^^^^^^^^^^^^^^
  File "/home/sfullerton24/python/lib/python3.11/site-packages/sqlalchemy/pool/impl.py", line 179, in _do_get
    with util.safe_reraise():
  File "/home/sfullerton24/python/lib/python3.11/site-packages/sqlalchemy/util/langhelpers.py", line 146, in __exit__
    raise exc_value.with_traceback(exc_tb)
  File "/home/sfullerton24/python/lib/python3.11/site-packages/sqlalchemy/pool/impl.py", line 177, in _do_get
    return self._create_connection()
           ^^^^^^^^^^^^^^^^^^^^^^^^^
  File "/home/sfullerton24/python/lib/python3.11/site-packages/sqlalchemy/pool/base.py", line 390, in _create_connection
    return _ConnectionRecord(self)
           ^^^^^^^^^^^^^^^^^^^^^^^
  File "/home/sfullerton24/python/lib/python3.11/site-packages/sqlalchemy/pool/base.py", line 674, in __init__
    self.__connect()
  File "/home/sfullerton24/python/lib/python3.11/site-packages/sqlalchemy/pool/base.py", line 900, in __connect
    with util.safe_reraise():
  File "/home/sfullerton24/python/lib/python3.11/site-packages/sqlalchemy/util/langhelpers.py", line 146, in __exit__
    raise exc_value.with_traceback(exc_tb)
  File "/home/sfullerton24/python/lib/python3.11/site-packages/sqlalchemy/pool/base.py", line 896, in __connect
    self.dbapi_connection = connection = pool._invoke_creator(self)
                                         ^^^^^^^^^^^^^^^^^^^^^^^^^^
  File "/home/sfullerton24/python/lib/python3.11/site-packages/sqlalchemy/engine/create.py", line 643, in connect
    return dialect.connect(*cargs, **cparams)
           ^^^^^^^^^^^^^^^^^^^^^^^^^^^^^^^^^^
  File "/home/sfullerton24/python/lib/python3.11/site-packages/sqlalchemy/engine/default.py", line 616, in connect
    return self.loaded_dbapi.connect(*cargs, **cparams)
           ^^^^^^^^^^^^^^^^^^^^^^^^^^^^^^^^^^^^^^^^^^^^
  File "/home/sfullerton24/python/lib/python3.11/site-packages/psycopg2/__init__.py", line 122, in connect
    conn = _connect(dsn, connection_factory=connection_factory, **kwasync)
           ^^^^^^^^^^^^^^^^^^^^^^^^^^^^^^^^^^^^^^^^^^^^^^^^^^^^^^^^^^^^^^^
psycopg2.OperationalError: could not connect to server: Connection refused
	Is the server running on host "localhost" (127.0.0.1) and accepting
	TCP/IP connections on port 7449?


The above exception was the direct cause of the following exception:

Traceback (most recent call last):
  File "/home/sfullerton24/twitter_postgres_parallel/load_tweets_batch.py", line 416, in <module>
    connection = engine.connect()
                 ^^^^^^^^^^^^^^^^
  File "/home/sfullerton24/python/lib/python3.11/site-packages/sqlalchemy/engine/base.py", line 3279, in connect
    return self._connection_cls(self)
           ^^^^^^^^^^^^^^^^^^^^^^^^^^
  File "/home/sfullerton24/python/lib/python3.11/site-packages/sqlalchemy/engine/base.py", line 147, in __init__
    Connection._handle_dbapi_exception_noconnection(
  File "/home/sfullerton24/python/lib/python3.11/site-packages/sqlalchemy/engine/base.py", line 2443, in _handle_dbapi_exception_noconnection
    raise sqlalchemy_exception.with_traceback(exc_info[2]) from e
  File "/home/sfullerton24/python/lib/python3.11/site-packages/sqlalchemy/engine/base.py", line 145, in __init__
    self._dbapi_connection = engine.raw_connection()
                             ^^^^^^^^^^^^^^^^^^^^^^^
  File "/home/sfullerton24/python/lib/python3.11/site-packages/sqlalchemy/engine/base.py", line 3303, in raw_connection
    return self.pool.connect()
           ^^^^^^^^^^^^^^^^^^^
  File "/home/sfullerton24/python/lib/python3.11/site-packages/sqlalchemy/pool/base.py", line 449, in connect
    return _ConnectionFairy._checkout(self)
           ^^^^^^^^^^^^^^^^^^^^^^^^^^^^^^^^
  File "/home/sfullerton24/python/lib/python3.11/site-packages/sqlalchemy/pool/base.py", line 1263, in _checkout
    fairy = _ConnectionRecord.checkout(pool)
            ^^^^^^^^^^^^^^^^^^^^^^^^^^^^^^^^
  File "/home/sfullerton24/python/lib/python3.11/site-packages/sqlalchemy/pool/base.py", line 712, in checkout
    rec = pool._do_get()
          ^^^^^^^^^^^^^^
  File "/home/sfullerton24/python/lib/python3.11/site-packages/sqlalchemy/pool/impl.py", line 179, in _do_get
    with util.safe_reraise():
  File "/home/sfullerton24/python/lib/python3.11/site-packages/sqlalchemy/util/langhelpers.py", line 146, in __exit__
    raise exc_value.with_traceback(exc_tb)
  File "/home/sfullerton24/python/lib/python3.11/site-packages/sqlalchemy/pool/impl.py", line 177, in _do_get
    return self._create_connection()
           ^^^^^^^^^^^^^^^^^^^^^^^^^
  File "/home/sfullerton24/python/lib/python3.11/site-packages/sqlalchemy/pool/base.py", line 390, in _create_connection
    return _ConnectionRecord(self)
           ^^^^^^^^^^^^^^^^^^^^^^^
  File "/home/sfullerton24/python/lib/python3.11/site-packages/sqlalchemy/pool/base.py", line 674, in __init__
    self.__connect()
  File "/home/sfullerton24/python/lib/python3.11/site-packages/sqlalchemy/pool/base.py", line 900, in __connect
    with util.safe_reraise():
  File "/home/sfullerton24/python/lib/python3.11/site-packages/sqlalchemy/util/langhelpers.py", line 146, in __exit__
    raise exc_value.with_traceback(exc_tb)
  File "/home/sfullerton24/python/lib/python3.11/site-packages/sqlalchemy/pool/base.py", line 896, in __connect
    self.dbapi_connection = connection = pool._invoke_creator(self)
                                         ^^^^^^^^^^^^^^^^^^^^^^^^^^
  File "/home/sfullerton24/python/lib/python3.11/site-packages/sqlalchemy/engine/create.py", line 643, in connect
    return dialect.connect(*cargs, **cparams)
           ^^^^^^^^^^^^^^^^^^^^^^^^^^^^^^^^^^
  File "/home/sfullerton24/python/lib/python3.11/site-packages/sqlalchemy/engine/default.py", line 616, in connect
    return self.loaded_dbapi.connect(*cargs, **cparams)
           ^^^^^^^^^^^^^^^^^^^^^^^^^^^^^^^^^^^^^^^^^^^^
  File "/home/sfullerton24/python/lib/python3.11/site-packages/psycopg2/__init__.py", line 122, in connect
    conn = _connect(dsn, connection_factory=connection_factory, **kwasync)
           ^^^^^^^^^^^^^^^^^^^^^^^^^^^^^^^^^^^^^^^^^^^^^^^^^^^^^^^^^^^^^^^
sqlalchemy.exc.OperationalError: (psycopg2.OperationalError) could not connect to server: Connection refused
	Is the server running on host "localhost" (127.0.0.1) and accepting
	TCP/IP connections on port 7449?

(Background on this error at: https://sqlalche.me/e/20/e3q8)
Traceback (most recent call last):
  File "/home/sfullerton24/python/lib/python3.11/site-packages/sqlalchemy/engine/base.py", line 145, in __init__
    self._dbapi_connection = engine.raw_connection()
                             ^^^^^^^^^^^^^^^^^^^^^^^
  File "/home/sfullerton24/python/lib/python3.11/site-packages/sqlalchemy/engine/base.py", line 3303, in raw_connection
    return self.pool.connect()
           ^^^^^^^^^^^^^^^^^^^
  File "/home/sfullerton24/python/lib/python3.11/site-packages/sqlalchemy/pool/base.py", line 449, in connect
    return _ConnectionFairy._checkout(self)
           ^^^^^^^^^^^^^^^^^^^^^^^^^^^^^^^^
  File "/home/sfullerton24/python/lib/python3.11/site-packages/sqlalchemy/pool/base.py", line 1263, in _checkout
    fairy = _ConnectionRecord.checkout(pool)
            ^^^^^^^^^^^^^^^^^^^^^^^^^^^^^^^^
  File "/home/sfullerton24/python/lib/python3.11/site-packages/sqlalchemy/pool/base.py", line 712, in checkout
    rec = pool._do_get()
          ^^^^^^^^^^^^^^
  File "/home/sfullerton24/python/lib/python3.11/site-packages/sqlalchemy/pool/impl.py", line 179, in _do_get
    with util.safe_reraise():
  File "/home/sfullerton24/python/lib/python3.11/site-packages/sqlalchemy/util/langhelpers.py", line 146, in __exit__
    raise exc_value.with_traceback(exc_tb)
  File "/home/sfullerton24/python/lib/python3.11/site-packages/sqlalchemy/pool/impl.py", line 177, in _do_get
    return self._create_connection()
           ^^^^^^^^^^^^^^^^^^^^^^^^^
  File "/home/sfullerton24/python/lib/python3.11/site-packages/sqlalchemy/pool/base.py", line 390, in _create_connection
    return _ConnectionRecord(self)
           ^^^^^^^^^^^^^^^^^^^^^^^
  File "/home/sfullerton24/python/lib/python3.11/site-packages/sqlalchemy/pool/base.py", line 674, in __init__
    self.__connect()
  File "/home/sfullerton24/python/lib/python3.11/site-packages/sqlalchemy/pool/base.py", line 900, in __connect
    with util.safe_reraise():
  File "/home/sfullerton24/python/lib/python3.11/site-packages/sqlalchemy/util/langhelpers.py", line 146, in __exit__
    raise exc_value.with_traceback(exc_tb)
  File "/home/sfullerton24/python/lib/python3.11/site-packages/sqlalchemy/pool/base.py", line 896, in __connect
    self.dbapi_connection = connection = pool._invoke_creator(self)
                                         ^^^^^^^^^^^^^^^^^^^^^^^^^^
  File "/home/sfullerton24/python/lib/python3.11/site-packages/sqlalchemy/engine/create.py", line 643, in connect
    return dialect.connect(*cargs, **cparams)
           ^^^^^^^^^^^^^^^^^^^^^^^^^^^^^^^^^^
  File "/home/sfullerton24/python/lib/python3.11/site-packages/sqlalchemy/engine/default.py", line 616, in connect
    return self.loaded_dbapi.connect(*cargs, **cparams)
           ^^^^^^^^^^^^^^^^^^^^^^^^^^^^^^^^^^^^^^^^^^^^
  File "/home/sfullerton24/python/lib/python3.11/site-packages/psycopg2/__init__.py", line 122, in connect
    conn = _connect(dsn, connection_factory=connection_factory, **kwasync)
           ^^^^^^^^^^^^^^^^^^^^^^^^^^^^^^^^^^^^^^^^^^^^^^^^^^^^^^^^^^^^^^^
psycopg2.OperationalError: could not connect to server: Connection refused
	Is the server running on host "localhost" (127.0.0.1) and accepting
	TCP/IP connections on port 7449?


The above exception was the direct cause of the following exception:

Traceback (most recent call last):
  File "/home/sfullerton24/twitter_postgres_parallel/load_tweets_batch.py", line 416, in <module>
    connection = engine.connect()
                 ^^^^^^^^^^^^^^^^
  File "/home/sfullerton24/python/lib/python3.11/site-packages/sqlalchemy/engine/base.py", line 3279, in connect
    return self._connection_cls(self)
           ^^^^^^^^^^^^^^^^^^^^^^^^^^
  File "/home/sfullerton24/python/lib/python3.11/site-packages/sqlalchemy/engine/base.py", line 147, in __init__
    Connection._handle_dbapi_exception_noconnection(
  File "/home/sfullerton24/python/lib/python3.11/site-packages/sqlalchemy/engine/base.py", line 2443, in _handle_dbapi_exception_noconnection
    raise sqlalchemy_exception.with_traceback(exc_info[2]) from e
  File "/home/sfullerton24/python/lib/python3.11/site-packages/sqlalchemy/engine/base.py", line 145, in __init__
    self._dbapi_connection = engine.raw_connection()
                             ^^^^^^^^^^^^^^^^^^^^^^^
  File "/home/sfullerton24/python/lib/python3.11/site-packages/sqlalchemy/engine/base.py", line 3303, in raw_connection
    return self.pool.connect()
           ^^^^^^^^^^^^^^^^^^^
  File "/home/sfullerton24/python/lib/python3.11/site-packages/sqlalchemy/pool/base.py", line 449, in connect
    return _ConnectionFairy._checkout(self)
           ^^^^^^^^^^^^^^^^^^^^^^^^^^^^^^^^
  File "/home/sfullerton24/python/lib/python3.11/site-packages/sqlalchemy/pool/base.py", line 1263, in _checkout
    fairy = _ConnectionRecord.checkout(pool)
            ^^^^^^^^^^^^^^^^^^^^^^^^^^^^^^^^
  File "/home/sfullerton24/python/lib/python3.11/site-packages/sqlalchemy/pool/base.py", line 712, in checkout
    rec = pool._do_get()
          ^^^^^^^^^^^^^^
  File "/home/sfullerton24/python/lib/python3.11/site-packages/sqlalchemy/pool/impl.py", line 179, in _do_get
    with util.safe_reraise():
  File "/home/sfullerton24/python/lib/python3.11/site-packages/sqlalchemy/util/langhelpers.py", line 146, in __exit__
    raise exc_value.with_traceback(exc_tb)
  File "/home/sfullerton24/python/lib/python3.11/site-packages/sqlalchemy/pool/impl.py", line 177, in _do_get
    return self._create_connection()
           ^^^^^^^^^^^^^^^^^^^^^^^^^
  File "/home/sfullerton24/python/lib/python3.11/site-packages/sqlalchemy/pool/base.py", line 390, in _create_connection
    return _ConnectionRecord(self)
           ^^^^^^^^^^^^^^^^^^^^^^^
  File "/home/sfullerton24/python/lib/python3.11/site-packages/sqlalchemy/pool/base.py", line 674, in __init__
    self.__connect()
  File "/home/sfullerton24/python/lib/python3.11/site-packages/sqlalchemy/pool/base.py", line 900, in __connect
    with util.safe_reraise():
  File "/home/sfullerton24/python/lib/python3.11/site-packages/sqlalchemy/util/langhelpers.py", line 146, in __exit__
    raise exc_value.with_traceback(exc_tb)
  File "/home/sfullerton24/python/lib/python3.11/site-packages/sqlalchemy/pool/base.py", line 896, in __connect
    self.dbapi_connection = connection = pool._invoke_creator(self)
                                         ^^^^^^^^^^^^^^^^^^^^^^^^^^
  File "/home/sfullerton24/python/lib/python3.11/site-packages/sqlalchemy/engine/create.py", line 643, in connect
    return dialect.connect(*cargs, **cparams)
           ^^^^^^^^^^^^^^^^^^^^^^^^^^^^^^^^^^
  File "/home/sfullerton24/python/lib/python3.11/site-packages/sqlalchemy/engine/default.py", line 616, in connect
    return self.loaded_dbapi.connect(*cargs, **cparams)
           ^^^^^^^^^^^^^^^^^^^^^^^^^^^^^^^^^^^^^^^^^^^^
  File "/home/sfullerton24/python/lib/python3.11/site-packages/psycopg2/__init__.py", line 122, in connect
    conn = _connect(dsn, connection_factory=connection_factory, **kwasync)
           ^^^^^^^^^^^^^^^^^^^^^^^^^^^^^^^^^^^^^^^^^^^^^^^^^^^^^^^^^^^^^^^
sqlalchemy.exc.OperationalError: (psycopg2.OperationalError) could not connect to server: Connection refused
	Is the server running on host "localhost" (127.0.0.1) and accepting
	TCP/IP connections on port 7449?

(Background on this error at: https://sqlalche.me/e/20/e3q8)
Command exited with non-zero status 10
4.11user 0.48system 0:00.78elapsed 589%CPU (0avgtext+0avgdata 43956maxresident)k
400inputs+2656outputs (0major+95000minor)pagefaults 0swaps
